Workbook

Sheet Setup
A1: ⚙ ATTENDANCE & PAYROLL SETUP — 2026
A3: GLOBAL SETTINGS | H3: PUBLIC HOLIDAYS (Optional)
A4: Year | B4: 2026 | H4: Date | I4: Holiday Name | J4: Paid?
A5: Shift Start (HH:MM) | B5: 08:00
A6: Shift End (HH:MM) | B6: 17:00
A7: Break (minutes) | B7: 60
A8: Paid Hours / Day | B8: 8 | C8: ℹ Standard paid hours per WORK day
A9: OT Multiplier | B9: 1.5 | C9: ℹ e.g. 1.5 = time-and-a-half
A10: Attendance Bonus (PKR) | B10: 0 | C10: ℹ Monthly bonus for zero absences
A13: EMPLOYEE MASTER LIST (add new employees below — sheets update automatically)
A14: # | B14: Employee Name | C14: Monthly Salary (PKR) | E14: Position / Role | F14: Department
A15: 1 | B15: Sheraz | C15: 38000
A16: 2 | B16: Zain | C16: 53000
A17: 3 | B17: Yousaf | C17: 28000
A18: 4 | B18: Hamza | C18: 25000
A19: 5 | B19: Amjad | C19: 25000
A20: 6 | B20: Tanveer | C20: 25000
A21: 7 | B21: Ali Zaman | C21: 75000
A22: 8 | B22: Awais Ali | C22: 25000
A23: 9 | B23: Ishtiaq | C23: 25000
A24: 10 | B24: Usama bhai | C24: 50000
A25: 11 | B25: Ahtisham | C25: 10000
A26: 12 | B26: Factory rent | C26: 77000
... A28: 14 | B28: Saqab | C28: 25000
A29: 15
A30: 16
A31: 17
A32: 18
A33: 19
A34: 20
A35: 21
A36: 22
A37: 23
A38: 24
A39: 25
A40: 26
... A44: 30
A45: TOTAL PAYROLL BUDGET (PKR) | C45: =SUM(C15:C44) -> 483500
A47: 💡 HOW TO USE: • Add new employee: type Name in col B and Salary in col C → auto-appears in ALL attendance & payroll sheets • Fill daily attendance hours in each month's sheet (blue cells) • Payroll sheets calculate automatically — no manual formulas needed

Sheet Annual_Summary
A1: 📊 ANNUAL PAYROLL SUMMARY — 2026
A3: Employee | B3: Jan | C3: Feb | D3: Mar | E3: Apr | F3: May | G3: Jun | H3: Jul | I3: Aug | J3: Sep | K3: Oct | L3: Nov | M3: Dec | N3: Annual Total
A4: =IF(Setup!B15<>"",Setup!B15,"") -> Sheraz | B4: =IF(Setup!B15<>"",Payroll_Jan!R8,"") -> 33302.778 | C4: =IF(Setup!B15<>"",Payroll_Feb!R8,"") -> 13546.875 | D4: =IF(Setup!B15<>"",Payroll_Mar!R8,"") -> 4285.5769 | E4: =IF(Setup!B15<>"",Payroll_Apr!R8,"") -> 4172.5962 | F4: =IF(Setup!B15<>"",Payroll_May!R8,"") -> 5195.6731 | G4: =IF(Setup!B15<>"",Payroll_Jun!R8,"") -> 33478.365 | H4: =IF(Setup!B15<>"",Payroll_Jul!R8,"") -> 15915.972 | I4: =IF(Setup!B15<>"",Payroll_Aug!R8,"") -> 0 | J4: =IF(Setup!B15<>"",Payroll_Sep!R8,"") -> 0 | K4: =IF(Setup!B15<>"",Payroll_Oct!R8,"") -> 0 | L4: =IF(Setup!B15<>"",Payroll_Nov!R8,"") -> 0 | M4: =IF(Setup!B15<>"",Payroll_Dec!R8,"") -> 0 | O4: =IF(Setup!B15<>"",SUM(B4:M4),"") -> 109897.84
A5: =IF(Setup!B16<>"",Setup!B16,"") -> Zain | B5: =IF(Setup!B16<>"",Payroll_Jan!R9,"") -> 52742.361 | C5: =IF(Setup!B16<>"",Payroll_Feb!R9,"") -> 20239.583 | D5: =IF(Setup!B16<>"",Payroll_Mar!R9,"") -> 12197.115 | E5: =IF(Setup!B16<>"",Payroll_Apr!R9,"") -> 14637.26 | F5: =IF(Setup!B16<>"",Payroll_May!R9,"") -> 3000 | G5: =IF(Setup!B16<>"",Payroll_Jun!R9,"") -> 19114.423 | H5: =IF(Setup!B16<>"",Payroll_Jul!R9,"") -> 15312.5 | I5: =IF(Setup!B16<>"",Payroll_Aug!R9,"") -> 0 | J5: =IF(Setup!B16<>"",Payroll_Sep!R9,"") -> 0 | K5: =IF(Setup!B16<>"",Payroll_Oct!R9,"") -> 0 | L5: =IF(Setup!B16<>"",Payroll_Nov!R9,"") -> 0 | M5: =IF(Setup!B16<>"",Payroll_Dec!R9,"") -> 0 | O5: =IF(Setup!B16<>"",SUM(B5:M5),"") -> 137243.24
A6: =IF(Setup!B17<>"",Setup!B17,"") -> Yousaf | B6: =IF(Setup!B17<>"",Payroll_Jan!R10,"") -> 27650 | C6: =IF(Setup!B17<>"",Payroll_Feb!R10,"") -> 18104.167 | D6: =IF(Setup!B17<>"",Payroll_Mar!R10,"") -> 9673.0769 | E6: =IF(Setup!B17<>"",Payroll_Apr!R10,"") -> 17711.538 | F6: =IF(Setup!B17<>"",Payroll_May!R10,"") -> 5886.5385 | G6: =IF(Setup!B17<>"",Payroll_Jun!R10,"") -> 1068.4615 | H6: =IF(Setup!B17<>"",Payroll_Jul!R10,"") -> 9333.3333 | I6: =IF(Setup!B17<>"",Payroll_Aug!R10,"") -> 0 | J6: =IF(Setup!B17<>"",Payroll_Sep!R10,"") -> 0 | K6: =IF(Setup!B17<>"",Payroll_Oct!R10,"") -> 0 | L6: =IF(Setup!B17<>"",Payroll_Nov!R10,"") -> 0 | M6: =IF(Setup!B17<>"",Payroll_Dec!R10,"") -> 0 | O6: =IF(Setup!B17<>"",SUM(B6:M6),"") -> 89427.115
A7: =IF(Setup!B18<>"",Setup!B18,"") -> Hamza | B7: =IF(Setup!B18<>"",Payroll_Jan!R11,"") -> 18784.722 | C7: =IF(Setup!B18<>"",Payroll_Feb!R11,"") -> 2388.0208 | D7: =IF(Setup!B18<>"",Payroll_Mar!R11,"") -> 9072.1154 | E7: =IF(Setup!B18<>"",Payroll_Apr!R11,"") -> 7274.0385 | F7: =IF(Setup!B18<>"",Payroll_May!R11,"") -> 0.0096153846 | G7: =IF(Setup!B18<>"",Payroll_Jun!R11,"") -> 9610.5673 | H7: =IF(Setup!B18<>"",Payroll_Jul!R11,"") -> 60.185185 | I7: =IF(Setup!B18<>"",Payroll_Aug!R11,"") -> 0 | J7: =IF(Setup!B18<>"",Payroll_Sep!R11,"") -> 0 | K7: =IF(Setup!B18<>"",Payroll_Oct!R11,"") -> 0 | L7: =IF(Setup!B18<>"",Payroll_Nov!R11,"") -> 0 | M7: =IF(Setup!B18<>"",Payroll_Dec!R11,"") -> 0 | O7: =IF(Setup!B18<>"",SUM(B7:M7),"") -> 47189.659
A8: =IF(Setup!B19<>"",Setup!B19,"") -> Amjad | B8: =IF(Setup!B19<>"",Payroll_Jan!R12,"") -> 29687.5 | C8: =IF(Setup!B19<>"",Payroll_Feb!R12,"") -> 13326.823 | D8: =IF(Setup!B19<>"",Payroll_Mar!R12,"") -> 11536.058 | E8: =IF(Setup!B19<>"",Payroll_Apr!R12,"") -> 16846.154 | F8: =IF(Setup!B19<>"",Payroll_May!R12,"") -> 7859.375 | G8: =IF(Setup!B19<>"",Payroll_Jun!R12,"") -> 18710.337 | H8: =IF(Setup!B19<>"",Payroll_Jul!R12,"") -> 15747.685 | I8: =IF(Setup!B19<>"",Payroll_Aug!R12,"") -> 0 | J8: =IF(Setup!B19<>"",Payroll_Sep!R12,"") -> 0 | K8: =IF(Setup!B19<>"",Payroll_Oct!R12,"") -> 0 | L8: =IF(Setup!B19<>"",Payroll_Nov!R12,"") -> 0 | M8: =IF(Setup!B19<>"",Payroll_Dec!R12,"") -> 0 | O8: =IF(Setup!B19<>"",SUM(B8:M8),"") -> 113713.93
A9: =IF(Setup!B20<>"",Setup!B20,"") -> Tanveer | B9: =IF(Setup!B20<>"",Payroll_Jan!R13,"") -> 15625 | C9: =IF(Setup!B20<>"",Payroll_Feb!R13,"") -> 11875 | D9: =IF(Setup!B20<>"",Payroll_Mar!R13,"") -> 10000 | E9: =IF(Setup!B20<>"",Payroll_Apr!R13,"") -> -1807.6923 | F9: =IF(Setup!B20<>"",Payroll_May!R13,"") -> 0 | G9: =IF(Setup!B20<>"",Payroll_Jun!R13,"") -> 10000 | H9: =IF(Setup!B20<>"",Payroll_Jul!R13,"") -> 15000 | I9: =IF(Setup!B20<>"",Payroll_Aug!R13,"") -> 0 | J9: =IF(Setup!B20<>"",Payroll_Sep!R13,"") -> 0 | K9: =IF(Setup!B20<>"",Payroll_Oct!R13,"") -> 0 | L9: =IF(Setup!B20<>"",Payroll_Nov!R13,"") -> 0 | M9: =IF(Setup!B20<>"",Payroll_Dec!R13,"") -> 0 | O9: =IF(Setup!B20<>"",SUM(B9:M9),"") -> 60692.308
A10: =IF(Setup!B21<>"",Setup!B21,"") -> Ali Zaman | B10: =IF(Setup!B21<>"",Payroll_Jan!R14,"") -> 74809.028 | C10: =IF(Setup!B21<>"",Payroll_Feb!R14,"") -> 75000 | D10: =IF(Setup!B21<>"",Payroll_Mar!R14,"") -> 45000 | E10: =IF(Setup!B21<>"",Payroll_Apr!R14,"") -> 38000 | F10: =IF(Setup!B21<>"",Payroll_May!R14,"") -> 35000 | G10: =IF(Setup!B21<>"",Payroll_Jun!R14,"") -> 55000 | H10: =IF(Setup!B21<>"",Payroll_Jul!R14,"") -> 45000 | I10: =IF(Setup!B21<>"",Payroll_Aug!R14,"") -> 0 | J10: =IF(Setup!B21<>"",Payroll_Sep!R14,"") -> 0 | K10: =IF(Setup!B21<>"",Payroll_Oct!R14,"") -> 0 | L10: =IF(Setup!B21<>"",Payroll_Nov!R14,"") -> 0 | M10: =IF(Setup!B21<>"",Payroll_Dec!R14,"") -> 0 | O10: =IF(Setup!B21<>"",SUM(B10:M10),"") -> 367809.03
A11: =IF(Setup!B22<>"",Setup!B22,"") -> Awais Ali | B11: =IF(Setup!B22<>"",Payroll_Jan!R15,"") -> 18750 | C11: =IF(Setup!B22<>"",Payroll_Feb!R15,"") -> 15838.542 | D11: =IF(Setup!B22<>"",Payroll_Mar!R15,"") -> 10508.413 | E11: =IF(Setup!B22<>"",Payroll_Apr!R15,"") -> 17341.346 | F11: =IF(Setup!B22<>"",Payroll_May!R15,"") -> 269.23077 | G11: =IF(Setup!B22<>"",Payroll_Jun!R15,"") -> 11591.346 | H11: =IF(Setup!B22<>"",Payroll_Jul!R15,"") -> 0 | I11: =IF(Setup!B22<>"",Payroll_Aug!R15,"") -> 0 | J11: =IF(Setup!B22<>"",Payroll_Sep!R15,"") -> 0 | K11: =IF(Setup!B22<>"",Payroll_Oct!R15,"") -> 0 | L11: =IF(Setup!B22<>"",Payroll_Nov!R15,"") -> 0 | M11: =IF(Setup!B22<>"",Payroll_Dec!R15,"") -> 0 | O11: =IF(Setup!B22<>"",SUM(B11:M11),"") -> 74298.878
A12: =IF(Setup!B23<>"",Setup!B23,"") -> Ishtiaq | B12: =IF(Setup!B23<>"",Payroll_Jan!R16,"") -> 29687.5 | C12: =IF(Setup!B23<>"",Payroll_Feb!R16,"") -> 12080.729 | D12: =IF(Setup!B23<>"",Payroll_Mar!R16,"") -> 8936.2981 | E12: =IF(Setup!B23<>"",Payroll_Apr!R16,"") -> 15265.024 | F12: =IF(Setup!B23<>"",Payroll_May!R16,"") -> 13935.096 | G12: =IF(Setup!B23<>"",Payroll_Jun!R16,"") -> 8070.9135 | H12: =IF(Setup!B23<>"",Payroll_Jul!R16,"") -> 0 | I12: =IF(Setup!B23<>"",Payroll_Aug!R16,"") -> 0 | J12: =IF(Setup!B23<>"",Payroll_Sep!R16,"") -> 0 | K12: =IF(Setup!B23<>"",Payroll_Oct!R16,"") -> 0 | L12: =IF(Setup!B23<>"",Payroll_Nov!R16,"") -> 0 | M12: =IF(Setup!B23<>"",Payroll_Dec!R16,"") -> 0 | O12: =IF(Setup!B23<>"",SUM(B12:M12),"") -> 87975.561
A13: =IF(Setup!B24<>"",Setup!B24,"") -> Usama bhai | B13: =IF(Setup!B24<>"",Payroll_Jan!R17,"") -> 31250 | C13: =IF(Setup!B24<>"",Payroll_Feb!R17,"") -> 50000 | D13: =IF(Setup!B24<>"",Payroll_Mar!R17,"") -> 50000 | E13: =IF(Setup!B24<>"",Payroll_Apr!R17,"") -> 50000 | F13: =IF(Setup!B24<>"",Payroll_May!R17,"") -> 0 | G13: =IF(Setup!B24<>"",Payroll_Jun!R17,"") -> 50000 | H13: =IF(Setup!B24<>"",Payroll_Jul!R17,"") -> 50000 | I13: =IF(Setup!B24<>"",Payroll_Aug!R17,"") -> 0 | J13: =IF(Setup!B24<>"",Payroll_Sep!R17,"") -> 0 | K13: =IF(Setup!B24<>"",Payroll_Oct!R17,"") -> 0 | L13: =IF(Setup!B24<>"",Payroll_Nov!R17,"") -> 0 | M13: =IF(Setup!B24<>"",Payroll_Dec!R17,"") -> 0 | O13: =IF(Setup!B24<>"",SUM(B13:M13),"") -> 281250
A14: =IF(Setup!B25<>"",Setup!B25,"") -> Ahtisham | B14: =IF(Setup!B25<>"",Payroll_Jan!R18,"") -> 7541.6667 | C14: =IF(Setup!B25<>"",Payroll_Feb!R18,"") -> 10000 | D14: =IF(Setup!B25<>"",Payroll_Mar!R18,"") -> 10000 | E14: =IF(Setup!B25<>"",Payroll_Apr!R18,"") -> 10000 | F14: =IF(Setup!B25<>"",Payroll_May!R18,"") -> 0 | G14: =IF(Setup!B25<>"",Payroll_Jun!R18,"") -> 0 | H14: =IF(Setup!B25<>"",Payroll_Jul!R18,"") -> 0 | I14: =IF(Setup!B25<>"",Payroll_Aug!R18,"") -> 0 | J14: =IF(Setup!B25<>"",Payroll_Sep!R18,"") -> 0 | K14: =IF(Setup!B25<>"",Payroll_Oct!R18,"") -> 0 | L14: =IF(Setup!B25<>"",Payroll_Nov!R18,"") -> 0 | M14: =IF(Setup!B25<>"",Payroll_Dec!R18,"") -> 0 | O14: =IF(Setup!B25<>"",SUM(B14:M14),"") -> 37541.667
A15: =IF(Setup!B26<>"",Setup!B26,"") -> Factory rent | B15: =IF(Setup!B26<>"",Payroll_Jan!R19,"") -> 77267.361 | C15: =IF(Setup!B26<>"",Payroll_Feb!R19,"") -> 77000 | D15: =IF(Setup!B26<>"",Payroll_Mar!R19,"") -> 77000 | E15: =IF(Setup!B26<>"",Payroll_Apr!R19,"") -> 77000 | F15: =IF(Setup!B26<>"",Payroll_May!R19,"") -> 77000 | G15: =IF(Setup!B26<>"",Payroll_Jun!R19,"") -> 77000 | H15: =IF(Setup!B26<>"",Payroll_Jul!R19,"") -> 77000 | I15: =IF(Setup!B26<>"",Payroll_Aug!R19,"") -> 0 | J15: =IF(Setup!B26<>"",Payroll_Sep!R19,"") -> 0 | K15: =IF(Setup!B26<>"",Payroll_Oct!R19,"") -> 0 | L15: =IF(Setup!B26<>"",Payroll_Nov!R19,"") -> 0 | M15: =IF(Setup!B26<>"",Payroll_Dec!R19,"") -> 0 | O15: =IF(Setup!B26<>"",SUM(B15:M15),"") -> 539267.36
... A33: =IF(Setup!B44<>"",Setup!B44,"") | B33: =IF(Setup!B44<>"",Payroll_Jan!R37,"") | C33: =IF(Setup!B44<>"",Payroll_Feb!R37,"") | D33: =IF(Setup!B44<>"",Payroll_Mar!R37,"") | E33: =IF(Setup!B44<>"",Payroll_Apr!R37,"") | F33: =IF(Setup!B44<>"",Payroll_May!R37,"") | G33: =IF(Setup!B44<>"",Payroll_Jun!R37,"") | H33: =IF(Setup!B44<>"",Payroll_Jul!R37,"") | I33: =IF(Setup!B44<>"",Payroll_Aug!R37,"") | J33: =IF(Setup!B44<>"",Payroll_Sep!R37,"") | K33: =IF(Setup!B44<>"",Payroll_Oct!R37,"") | L33: =IF(Setup!B44<>"",Payroll_Nov!R37,"") | M33: =IF(Setup!B44<>"",Payroll_Dec!R37,"") | O33: =IF(Setup!B44<>"",SUM(B33:M33),"")
A34: Monthly Total | B34: =SUM(B4:B33) -> 417097.92 | C34: =SUM(C4:C33) -> 321899.74 | D34: =SUM(D4:D33) -> 260708.65 | E34: =SUM(E4:E33) -> 268940.26 | F34: =SUM(F4:F33) -> 156841.84 | G34: =SUM(G4:G33) -> 308860.76 | H34: =SUM(H4:H33) -> 258624.31 | I34: =SUM(I4:I33) -> 0 | ... O34: =SUM(O4:O33) -> 1992973.5

Sheet Attendance_Jan
A1: 📅 DAILY ATTENDANCE — JANUARY 2026
A2: Month | B2: January 2026
A3: Paid Hours/Day | B3: =Setup!B8 -> 8
A4: Required Working Hours | B4: 216
A6: Date | B6: Day | C6: Type | D6: Req Hrs | E6: =Setup!B15 -> Sheraz | F6: =Setup!B16 -> Zain | G6: =Setup!B17 -> Yousaf | H6: =Setup!B18 -> Hamza | I6: =Setup!B19 -> Amjad | J6: =Setup!B20 -> Tanveer | K6: =Setup!B21 -> Ali Zaman | L6: =Setup!B22 -> Awais Ali | M6: =Setup!B23 -> Ishtiaq | N6: =Setup!B24 -> Usama bhai | O6: =Setup!B25 -> Ahtisham | P6: =Setup!B26 -> Factory rent | Q6: =Setup!B27 -> Internet bill | R6: =Setup!B28 -> Saqab | S6: =Setup!B29 -> 0 | T6: =Setup!B30 -> 0 | U6: =Setup!B31 -> 0 | V6: =Setup!B32 -> 0 | W6: =Setup!B33 -> 0 | X6: =Setup!B34 -> 0 | Y6: =Setup!B35 -> 0 | Z6: =Setup!B36 -> 0 | AA6: =Setup!B37 -> 0 | AB6: =Setup!B38 -> 0 | AC6: =Setup!B39 -> 0 | AD6: =Setup!B40 -> 0 | AE6: =Setup!B41 -> 0 | AF6: =Setup!B42 -> 0 | AG6: =Setup!B43 -> 0 | AH6: =Setup!B44 -> 0
A7: 46023 | B7: Thu | C7: WORK | D7: 8 | E7: 7.3 | F7: 8.1 | G7: 8 | H7: 6 | I7: 9 | J7: 5 | K7: 8 | L7: 6 | M7: 9 | N7: 5 | O7: 6 | P7: 8 | Q7: 0 | R7: 0
A8: 46024 | B8: Fri | C8: WORK | D8: 8 | E8: 7 | F8: 8 | G8: 8 | H8: 6 | I8: 9 | J8: 5 | K8: 8 | L8: 6 | M8: 9 | N8: 5 | O8: 6 | P8: 8 | Q8: 0 | R8: 0
A9: 46025 | B9: Sat | C9: WORK | D9: 8 | E9: 7 | F9: 8 | G9: 8 | H9: 6 | I9: 9 | J9: 5 | K9: 8 | L9: 6 | M9: 9 | N9: 5 | O9: 6 | P9: 8 | Q9: 0 | R9: 0
A10: 46026 | B10: OFF | C10: OFF | D10: 0 | E10: 0 | F10: 0 | G10: 0 | H10: 0 | I10: 0 | J10: 0 | K10: 0 | L10: 0 | M10: 0 | N10: 0 | O10: 0 | P10: 0 | Q10: 0 | R10: 0 | S10: 0 | T10: 0 | U10: 0 | V10: 0 | W10: 0 | X10: 0 | Y10: 0 | Z10: 0 | AA10: 0 | AB10: 0 | AC10: 0 | AD10: 0 | AE10: 0 | AF10: 0 | AG10: 0 | AH10: 0
A11: 46027 | B11: Mon | C11: WORK | D11: 8 | E11: 7 | F11: 8 | G11: 8 | H11: 6 | I11: 9 | J11: 5 | K11: 8 | L11: 6 | M11: 9 | N11: 5 | O11: 6 | P11: 8.5 | Q11: 0 | R11: 0
A12: 46028 | B12: Tue | C12: WORK | D12: 8 | E12: 7 | F12: 8 | G12: 8 | H12: 6 | I12: 9 | J12: 5 | K12: 8 | L12: 6 | M12: 9 | N12: 5 | O12: 6 | P12: 8 | Q12: 0 | R12: 0
A13: 46029 | B13: Wed | C13: WORK | D13: 8 | E13: 7 | F13: 8 | G13: 8 | H13: 6 | I13: 9 | J13: 5 | K13: 8 | L13: 6 | M13: 9 | N13: 5 | O13: 6.4 | P13: 8 | Q13: 0 | R13: 0
A14: 46030 | B14: Thu | C14: WORK | D14: 8 | E14: 7 | F14: 8 | G14: 8 | H14: 6 | I14: 9 | J14: 5 | K14: 8 | L14: 6 | M14: 9 | N14: 5 | O14: 6 | P14: 8 | Q14: 0 | R14: 0
A15: 46031 | B15: Fri | C15: WORK | D15: 8 | E15: 7 | F15: 8 | G15: 5 | H15: 6 | I15: 9 | J15: 5 | K15: 8 | L15: 6 | M15: 9 | N15: 5 | O15: 6 | P15: 8 | Q15: 0 | R15: 0
A16: 46032 | B16: Sat | C16: WORK | D16: 8 | E16: 7 | F16: 8 | G16: 8 | H16: 6 | I16: 9 | J16: 5 | K16: 8 | L16: 6 | M16: 9 | N16: 5 | O16: 6 | P16: 8 | Q16: 0 | R16: 0
A17: 46033 | B17: OFF | C17: OFF | D17: 0 | E17: 0 | F17: 0 | G17: 0 | H17: 0 | I17: 0 | J17: 0 | K17: 0 | L17: 0 | M17: 0 | N17: 0 | O17: 0 | P17: 0 | Q17: 0 | R17: 0 | S17: 0 | T17: 0 | U17: 0 | V17: 0 | W17: 0 | X17: 0 | Y17: 0 | Z17: 0 | AA17: 0 | AB17: 0 | AC17: 0 | AD17: 0 | AE17: 0 | AF17: 0 | AG17: 0 | AH17: 0
A18: 46034 | B18: Mon | C18: WORK | D18: 8 | E18: 7 | F18: 8 | G18: 8 | H18: 6.3 | I18: 9 | J18: 5 | K18: 8 | L18: 6 | M18: 9 | N18: 5 | O18: 6 | P18: 8 | Q18: 0 | R18: 0
A19: 46035 | B19: Tue | C19: WORK | D19: 8 | E19: 7 | F19: 8 | G19: 8 | H19: 6 | I19: 9 | J19: 5 | K19: 8 | L19: 6 | M19: 9 | N19: 5 | O19: 6 | P19: 8 | Q19: 0 | R19: 0
A20: 46036 | B20: Wed | C20: WORK | D20: 8 | E20: 7 | F20: 8 | G20: 8 | H20: 6 | I20: 9 | J20: 5 | K20: 8 | L20: 6 | M20: 9 | N20: 5 | O20: 6 | P20: 8 | Q20: 0 | R20: 0
A21: 46037 | B21: Thu | C21: WORK | D21: 8 | E21: 7 | F21: 8 | G21: 8.3 | H21: 6 | I21: 9 | J21: 5 | K21: 7.45 | L21: 6 | M21: 9 | N21: 5 | O21: 6 | P21: 8 | Q21: 0 | R21: 0
A22: 46038 | B22: Fri | C22: WORK | D22: 8 | E22: 7 | F22: 8 | G22: 8 | H22: 6 | I22: 9 | J22: 5 | K22: 8 | L22: 6 | M22: 9 | N22: 5 | O22: 6 | P22: 8 | Q22: 0 | R22: 0
A23: 46039 | B23: Sat | C23: WORK | D23: 8 | E23: 7 | F23: 8 | G23: 8 | H23: 6 | I23: 9 | J23: 5 | K23: 8 | L23: 6 | M23: 9 | N23: 5 | O23: 6 | P23: 8 | Q23: 0 | R23: 0
A24: 46040 | B24: OFF | C24: OFF | D24: 0 | E24: 0 | F24: 0 | G24: 0 | H24: 0 | I24: 0 | J24: 0 | K24: 0 | L24: 0 | M24: 0 | N24: 0 | O24: 0 | P24: 0 | Q24: 0 | R24: 0 | S24: 0 | T24: 0 | U24: 0 | V24: 0 | W24: 0 | X24: 0 | Y24: 0 | Z24: 0 | AA24: 0 | AB24: 0 | AC24: 0 | AD24: 0 | AE24: 0 | AF24: 0 | AG24: 0 | AH24: 0
A25: 46041 | B25: Mon | C25: WORK | D25: 8 | E25: 7 | F25: 8 | G25: 8 | H25: 6 | I25: 9 | J25: 5 | K25: 8 | L25: 6 | M25: 9 | N25: 5 | O25: 6 | P25: 8 | Q25: 0 | R25: 0
A26: 46042 | B26: Tue | C26: WORK | D26: 8 | E26: 7 | F26: 8 | G26: 8 | H26: 6 | I26: 9 | J26: 5 | K26: 8 | L26: 6 | M26: 9 | N26: 5 | O26: 6.5 | P26: 8 | Q26: 0 | R26: 0
A27: 46043 | B27: Wed | C27: WORK | D27: 8 | E27: 7 | F27: 8 | G27: 8 | H27: 6 | I27: 9 | J27: 5 | K27: 8 | L27: 6 | M27: 9 | N27: 5 | O27: 6 | P27: 8 | Q27: 0 | R27: 0
A28: 46044 | B28: Thu | C28: WORK | D28: 8 | E28: 7 | F28: 8 | G28: 8 | H28: 6 | I28: 9 | J28: 5 | K28: 8 | L28: 6 | M28: 9 | N28: 5 | O28: 6 | P28: 8 | Q28: 0 | R28: 0
A29: 46045 | B29: Fri | C29: WORK | D29: 8 | E29: 7 | F29: 8 | G29: 8 | H29: 6 | I29: 9 | J29: 5 | K29: 8 | L29: 6 | M29: 9 | N29: 5 | O29: 6 | P29: 8 | Q29: 0 | R29: 0
A30: 46046 | B30: Sat | C30: WORK | D30: 8 | E30: 7 | F30: 8 | G30: 8 | H30: 6 | I30: 9 | J30: 5 | K30: 8 | L30: 6 | M30: 9 | N30: 5 | O30: 6 | P30: 8 | Q30: 0 | R30: 0
A31: 46047 | B31: OFF | C31: OFF | D31: 0 | E31: 0 | F31: 0 | G31: 0 | H31: 0 | I31: 0 | J31: 0 | K31: 0 | L31: 0 | M31: 0 | N31: 0 | O31: 0 | P31: 0 | Q31: 0 | R31: 0 | S31: 0 | T31: 0 | U31: 0 | V31: 0 | W31: 0 | X31: 0 | Y31: 0 | Z31: 0 | AA31: 0 | AB31: 0 | AC31: 0 | AD31: 0 | AE31: 0 | AF31: 0 | AG31: 0 | AH31: 0
A32: 46048 | B32: Mon | C32: WORK | D32: 8 | E32: 7 | F32: 8 | G32: 8 | H32: 6 | I32: 9 | J32: 5 | K32: 8 | L32: 6 | M32: 9 | N32: 5 | O32: 6 | P32: 8 | Q32: 0 | R32: 0
A33: 46049 | B33: Tue | C33: WORK | D33: 8 | E33: 7 | F33: 8 | G33: 8 | H33: 6 | I33: 9 | J33: 5 | K33: 8 | L33: 6 | M33: 9 | N33: 5 | O33: 6 | P33: 8 | Q33: 0 | R33: 0
A34: 46050 | B34: Wed | C34: WORK | D34: 8 | E34: 7 | F34: 7.3 | G34: 8 | H34: 6 | I34: 9 | J34: 5 | K34: 8 | L34: 6 | M34: 9 | N34: 5 | O34: 6 | P34: 8 | Q34: 0 | R34: 0
A35: 46051 | B35: Thu | C35: WORK | D35: 8 | E35: 7 | F35: 7.55 | G35: 8 | H35: 6 | I35: 9 | J35: 5 | K35: 8 | L35: 6 | M35: 9 | N35: 5 | O35: 6 | P35: 8 | Q35: 0 | R35: 0
A36: 46052 | B36: Fri | C36: WORK | D36: 8 | E36: 7 | F36: 8 | G36: 8 | H36: 6 | I36: 9 | J36: 5 | K36: 8 | L36: 6 | M36: 9 | N36: 5 | O36: 6 | P36: 8 | Q36: 0 | R36: 0
A37: 46053 | B37: Sat | C37: WORK | D37: 8 | E37: 7 | F37: 8 | G37: 8 | H37: 6 | I37: 9 | J37: 5 | K37: 8 | L37: 6 | M37: 9 | N37: 5 | O37: 6 | P37: 8 | Q37: 0 | R37: 0
A39: TOTALS | E39: =IF(Setup!B15<>"",SUM(E7:E37),"") -> 189.3 | F39: =IF(Setup!B16<>"",SUM(F7:F37),"") -> 214.95 | G39: =IF(Setup!B17<>"",SUM(G7:G37),"") -> 213.3 | H39: =IF(Setup!B18<>"",SUM(H7:H37),"") -> 162.3 | I39: =IF(Setup!B19<>"",SUM(I7:I37),"") -> 243 | J39: =IF(Setup!B20<>"",SUM(J7:J37),"") -> 135 | K39: =IF(Setup!B21<>"",SUM(K7:K37),"") -> 215.45 | L39: =IF(Setup!B22<>"",SUM(L7:L37),"") -> 162 | M39: =IF(Setup!B23<>"",SUM(M7:M37),"") -> 243 | N39: =IF(Setup!B24<>"",SUM(N7:N37),"") -> 135 | O39: =IF(Setup!B25<>"",SUM(O7:O37),"") -> 162.9 | P39: =IF(Setup!B26<>"",SUM(P7:P37),"") -> 216.5 | Q39: =IF(Setup!B27<>"",SUM(Q7:Q37),"") -> 0 | R39: =IF(Setup!B28<>"",SUM(R7:R37),"") -> 0 | S39: =IF(Setup!B29<>"",SUM(S7:S37),"") | T39: =IF(Setup!B30<>"",SUM(T7:T37),"") | U39: =IF(Setup!B31<>"",SUM(U7:U37),"") | V39: =IF(Setup!B32<>"",SUM(V7:V37),"") | W39: =IF(Setup!B33<>"",SUM(W7:W37),"") | X39: =IF(Setup!B34<>"",SUM(X7:X37),"") | Y39: =IF(Setup!B35<>"",SUM(Y7:Y37),"") | Z39: =IF(Setup!B36<>"",SUM(Z7:Z37),"") | AA39: =IF(Setup!B37<>"",SUM(AA7:AA37),"") | AB39: =IF(Setup!B38<>"",SUM(AB7:AB37),"") | AC39: =IF(Setup!B39<>"",SUM(AC7:AC37),"") | AD39: =IF(Setup!B40<>"",SUM(AD7:AD37),"") | AE39: =IF(Setup!B41<>"",SUM(AE7:AE37),"") | AF39: =IF(Setup!B42<>"",SUM(AF7:AF37),"") | AG39: =IF(Setup!B43<>"",SUM(AG7:AG37),"") | AH39: =IF(Setup!B44<>"",SUM(AH7:AH37),"")
A40: Absent Days (WORK days with 0 hrs) | E40: =IF(Setup!B15<>"",COUNTIFS(C7:C37,"WORK",E7:E37,0),"") -> 0 | F40: =IF(Setup!B16<>"",COUNTIFS(C7:C37,"WORK",F7:F37,0),"") -> 0 | G40: =IF(Setup!B17<>"",COUNTIFS(C7:C37,"WORK",G7:G37,0),"") -> 0 | H40: =IF(Setup!B18<>"",COUNTIFS(C7:C37,"WORK",H7:H37,0),"") -> 0 | I40: =IF(Setup!B19<>"",COUNTIFS(C7:C37,"WORK",I7:I37,0),"") -> 0 | J40: =IF(Setup!B20<>"",COUNTIFS(C7:C37,"WORK",J7:J37,0),"") -> 0 | K40: =IF(Setup!B21<>"",COUNTIFS(C7:C37,"WORK",K7:K37,0),"") -> 0 | L40: =IF(Setup!B22<>"",COUNTIFS(C7:C37,"WORK",L7:L37,0),"") -> 0 | M40: =IF(Setup!B23<>"",COUNTIFS(C7:C37,"WORK",M7:M37,0),"") -> 0 | N40: =IF(Setup!B24<>"",COUNTIFS(C7:C37,"WORK",N7:N37,0),"") -> 0 | O40: =IF(Setup!B25<>"",COUNTIFS(C7:C37,"WORK",O7:O37,0),"") -> 0 | P40: =IF(Setup!B26<>"",COUNTIFS(C7:C37,"WORK",P7:P37,0),"") -> 0 | Q40: =IF(Setup!B27<>"",COUNTIFS(C7:C37,"WORK",Q7:Q37,0),"") -> 27 | R40: =IF(Setup!B28<>"",COUNTIFS(C7:C37,"WORK",R7:R37,0),"") -> 27 | S40: =IF(Setup!B29<>"",COUNTIFS(C7:C37,"WORK",S7:S37,0),"") | T40: =IF(Setup!B30<>"",COUNTIFS(C7:C37,"WORK",T7:T37,0),"") | U40: =IF(Setup!B31<>"",COUNTIFS(C7:C37,"WORK",U7:U37,0),"") | V40: =IF(Setup!B32<>"",COUNTIFS(C7:C37,"WORK",V7:V37,0),"") | W40: =IF(Setup!B33<>"",COUNTIFS(C7:C37,"WORK",W7:W37,0),"") | X40: =IF(Setup!B34<>"",COUNTIFS(C7:C37,"WORK",X7:X37,0),"") | Y40: =IF(Setup!B35<>"",COUNTIFS(C7:C37,"WORK",Y7:Y37,0),"") | Z40: =IF(Setup!B36<>"",COUNTIFS(C7:C37,"WORK",Z7:Z37,0),"") | AA40: =IF(Setup!B37<>"",COUNTIFS(C7:C37,"WORK",AA7:AA37,0),"") | AB40: =IF(Setup!B38<>"",COUNTIFS(C7:C37,"WORK",AB7:AB37,0),"") | AC40: =IF(Setup!B39<>"",COUNTIFS(C7:C37,"WORK",AC7:AC37,0),"") | AD40: =IF(Setup!B40<>"",COUNTIFS(C7:C37,"WORK",AD7:AD37,0),"") | AE40: =IF(Setup!B41<>"",COUNTIFS(C7:C37,"WORK",AE7:AE37,0),"") | AF40: =IF(Setup!B42<>"",COUNTIFS(C7:C37,"WORK",AF7:AF37,0),"") | AG40: =IF(Setup!B43<>"",COUNTIFS(C7:C37,"WORK",AG7:AG37,0),"") | AH40: =IF(Setup!B44<>"",COUNTIFS(C7:C37,"WORK",AH7:AH37,0),"")

Sheet Attendance_Feb
A1: 📅 DAILY ATTENDANCE — FEBRUARY 2026
A2: Month | B2: February 2026
A3: Paid Hours/Day | B3: =Setup!B8 -> 8
A4: Required Working Hours | B4: 192
A6: Date | B6: Day | C6: Type | D6: Req Hrs | E6: =Setup!B15 -> Sheraz | F6: =Setup!B16 -> Zain | G6: =Setup!B17 -> Yousaf | H6: =Setup!B18 -> Hamza | I6: =Setup!B19 -> Amjad | J6: =Setup!B20 -> Tanveer | K6: =Setup!B21 -> Ali Zaman | L6: =Setup!B22 -> Awais Ali | M6: =Setup!B23 -> Ishtiaq | N6: =Setup!B24 -> Usama bhai | O6: =Setup!B25 -> Ahtisham | P6: =Setup!B26 -> Factory rent | Q6: =Setup!B27 -> Internet bill | R6: =Setup!B28 -> Saqab | S6: =Setup!B29 -> 0 | T6: =Setup!B30 -> 0 | U6: =Setup!B31 -> 0 | V6: =Setup!B32 -> 0 | W6: =Setup!B33 -> 0 | X6: =Setup!B34 -> 0 | Y6: =Setup!B35 -> 0 | Z6: =Setup!B36 -> 0 | AA6: =Setup!B37 -> 0 | AB6: =Setup!B38 -> 0 | AC6: =Setup!B39 -> 0 | AD6: =Setup!B40 -> 0 | AE6: =Setup!B41 -> 0 | AF6: =Setup!B42 -> 0 | AG6: =Setup!B43 -> 0 | AH6: =Setup!B44 -> 0
A7: 46054 | B7: OFF | C7: OFF | D7: 0 | R7: 0 | S7: 0 | T7: 0 | U7: 0 | V7: 0 | W7: 0 | X7: 0 | Y7: 0 | Z7: 0 | AA7: 0 | AB7: 0 | AC7: 0 | AD7: 0 | AE7: 0 | AF7: 0 | AG7: 0 | AH7: 0
A8: 46055 | B8: Mon | C8: WORK | D8: 8 | E8: 8 | F8: 8 | G8: 8 | H8: 8 | I8: 8 | J8: A | K8: 8 | L8: 8 | M8: 8 | N8: 8 | O8: 8 | P8: 8 | Q8: 8
A9: 46056 | B9: Tue | C9: WORK | D9: 8 | E9: 8 | F9: 8 | G9: 8 | H9: 7.55 | I9: 8 | J9: 8 | K9: 8 | L9: 8 | M9: 7.5 | N9: 8 | O9: 8 | P9: 8 | Q9: 8
A10: 46057 | B10: Wed | C10: WORK | D10: 8 | E10: 8 | F10: 7.53 | G10: 7.53 | H10: 7.4 | I10: 7.53 | J10: 8 | K10: 8 | L10: 7.53 | M10: 7.53 | N10: 8 | O10: 8 | P10: 8 | Q10: 8
A11: 46058 | B11: Thu | C11: WORK | D11: 8 | E11: A | F11: 8 | G11: 8 | H11: 8 | I11: 4.45 | J11: 8 | K11: 8 | L11: 8 | M11: 8 | N11: 8 | O11: 8 | P11: 8 | Q11: 8
A12: 46059 | B12: Fri | C12: WORK | D12: 8 | E12: A | F12: 7.52 | G12: 7.52 | H12: 8 | I12: A | J12: 8 | K12: 8 | L12: 8 | M12: A | N12: 8 | O12: 8 | P12: 8 | Q12: 8
A13: 46060 | B13: Sat | C13: WORK | D13: 8 | E13: 8 | F13: 8 | G13: 8 | H13: 8 | I13: 8 | J13: 8 | K13: 8 | L13: 8 | M13: 8 | N13: 8 | O13: 8 | P13: 8 | Q13: 8
A14: 46061 | B14: OFF | C14: OFF | D14: 0 | R14: 0 | S14: 0 | T14: 0 | U14: 0 | V14: 0 | W14: 0 | X14: 0 | Y14: 0 | Z14: 0 | AA14: 0 | AB14: 0 | AC14: 0 | AD14: 0 | AE14: 0 | AF14: 0 | AG14: 0 | AH14: 0
A15: 46062 | B15: Mon | C15: WORK | D15: 8 | E15: 8 | F15: 7.5 | G15: 7.5 | H15: 8 | I15: 7.5 | J15: 8 | K15: 8 | L15: 8 | M15: 7.45 | N15: 8 | O15: 8 | P15: 8 | Q15: 8
A16: 46063 | B16: Tue | C16: WORK | D16: 8 | E16: 8 | F16: 8 | G16: 8 | H16: 8 | I16: 7.5 | J16: 8 | K16: 8 | L16: 8 | M16: 8 | N16: 8 | O16: 8 | P16: 8 | Q16: 8
A17: 46064 | B17: Wed | C17: WORK | D17: 8 | E17: 7.5 | F17: 8 | G17: 8 | H17: 7.55 | I17: 7.5 | J17: 8 | K17: 8 | L17: 7.55 | M17: 8 | N17: 8 | O17: 8 | P17: 8 | Q17: 8
A18: 46065 | B18: Thu | C18: WORK | D18: 8 | E18: 8 | F18: 8 | G18: 8 | H18: 7.4 | I18: 7.55 | J18: 8 | K18: 8 | L18: 7.55 | M18: 8 | N18: 8 | O18: 8 | P18: 8 | Q18: 8
A19: 46066 | B19: Fri | C19: WORK | D19: 8 | E19: 8 | F19: 8 | G19: A | H19: 7.5 | I19: A | J19: 8 | K19: 8 | L19: 7.5 | M19: 7.45 | N19: 8 | O19: 8 | P19: 8 | Q19: 8
A20: 46067 | B20: Sat | C20: WORK | D20: 8 | E20: 8 | F20: 8 | G20: 8 | H20: 7.5 | I20: 8 | J20: A | K20: 8 | L20: 8 | M20: 8 | N20: 8 | O20: 8 | P20: 8 | Q20: 8
A21: 46068 | B21: OFF | C21: OFF | D21: 0 | R21: 0 | S21: 0 | T21: 0 | U21: 0 | V21: 0 | W21: 0 | X21: 0 | Y21: 0 | Z21: 0 | AA21: 0 | AB21: 0 | AC21: 0 | AD21: 0 | AE21: 0 | AF21: 0 | AG21: 0 | AH21: 0
A22: 46069 | B22: Mon | C22: WORK | D22: 8 | E22: 8 | F22: 8 | G22: 8 | H22: 7.4 | I22: 8 | J22: A | K22: 8 | L22: 8 | M22: 5 | N22: 8 | O22: 8 | P22: 8 | Q22: 8
A23: 46070 | B23: Tue | C23: WORK | D23: 8 | E23: 5 | F23: 8 | G23: 8 | H23: 8 | I23: 8 | J23: 8 | K23: 8 | L23: 7.45 | M23: 8 | N23: 8 | O23: 8 | P23: 8 | Q23: 8
A24: 46071 | B24: Wed | C24: WORK | D24: 8 | E24: 8 | F24: 8 | G24: 5 | H24: 5.4 | I24: 3.55 | J24: 8 | K24: 8 | L24: 7.55 | M24: 7.55 | N24: 8 | O24: 8 | P24: 8 | Q24: 8
A25: 46072 | B25: Thu | C25: WORK | D25: 8 | E25: 8 | F25: 8 | G25: 8 | H25: 7.5 | I25: 7.53 | J25: 8 | K25: 8 | L25: 8 | M25: 8 | N25: 8 | O25: 8 | P25: 8 | Q25: 8
A26: 46073 | B26: Fri | C26: WORK | D26: 8 | E26: 8 | F26: 8 | G26: 8 | H26: 8 | I26: 8 | J26: 8 | K26: 8 | L26: 8 | M26: 8 | N26: 8 | O26: 8 | P26: 8 | Q26: 8
A27: 46074 | B27: Sat | C27: WORK | D27: 8 | E27: 8 | F27: 8 | G27: 8 | H27: A | I27: A | J27: 8 | K27: 8 | L27: 8 | M27: 8 | N27: 8 | O27: 8 | P27: 8 | Q27: 8
A28: 46075 | B28: OFF | C28: OFF | D28: 0 | R28: 0 | S28: 0 | T28: 0 | U28: 0 | V28: 0 | W28: 0 | X28: 0 | Y28: 0 | Z28: 0 | AA28: 0 | AB28: 0 | AC28: 0 | AD28: 0 | AE28: 0 | AF28: 0 | AG28: 0 | AH28: 0
A29: 46076 | B29: Mon | C29: WORK | D29: 8 | E29: 8 | F29: A | G29: 8 | H29: 8 | I29: 8 | J29: 8 | K29: 8 | L29: 3 | M29: A | N29: 8 | O29: 8 | P29: 8 | Q29: 8
A30: 46077 | B30: Tue | C30: WORK | D30: 8 | E30: 8 | F30: 7.45 | G30: 7.45 | H30: A | I30: 7.5 | J30: 8 | K30: 8 | L30: 8 | M30: 8 | N30: 8 | O30: 8 | P30: 8 | Q30: 8
A31: 46078 | B31: Wed | C31: WORK | D31: 8 | E31: 5 | F31: 8 | G31: 8 | H31: 8 | I31: 8 | J31: 8 | K31: 8 | L31: 7.5 | M31: 8 | N31: 8 | O31: 8 | P31: 8 | Q31: 8
A32: 46079 | B32: Thu | C32: WORK | D32: 8 | E32: 8 | F32: 8 | G32: 8 | H32: 8 | I32: 8 | J32: 8 | K32: 8 | L32: 8 | M32: 7.1 | N32: 8 | O32: 8 | P32: 8 | Q32: 8
A33: 46080 | B33: Fri | C33: WORK | D33: 8 | E33: 8 | F33: 8 | G33: 8 | H33: 7.45 | I33: 8 | J33: 8 | K33: 8 | L33: 8 | M33: 8 | N33: 8 | O33: 8 | P33: 8 | Q33: 8
A34: 46081 | B34: Sat | C34: WORK | D34: 8 | E34: 8 | F34: 8 | G34: 8 | H34: 7.45 | I34: 7.5 | J34: 8 | K34: 8 | L34: 7.45 | M34: 8 | N34: 8 | O34: 8 | P34: 8 | Q34: 8
A36: TOTALS | E36: =IF(Setup!B15<>"",SUM(E7:E34),"") -> 169.5 | F36: =IF(Setup!B16<>"",SUM(F7:F34),"") -> 182 | G36: =IF(Setup!B17<>"",SUM(G7:G34),"") -> 179 | H36: =IF(Setup!B18<>"",SUM(H7:H34),"") -> 168.1 | I36: =IF(Setup!B19<>"",SUM(I7:I34),"") -> 156.11 | J36: =IF(Setup!B20<>"",SUM(J7:J34),"") -> 168 | K36: =IF(Setup!B21<>"",SUM(K7:K34),"") -> 192 | L36: =IF(Setup!B22<>"",SUM(L7:L34),"") -> 183.08 | M36: =IF(Setup!B23<>"",SUM(M7:M34),"") -> 169.58 | N36: =IF(Setup!B24<>"",SUM(N7:N34),"") -> 192 | O36: =IF(Setup!B25<>"",SUM(O7:O34),"") -> 192 | P36: =IF(Setup!B26<>"",SUM(P7:P34),"") -> 192 | Q36: =IF(Setup!B27<>"",SUM(Q7:Q34),"") -> 192 | R36: =IF(Setup!B28<>"",SUM(R7:R34),"") -> 0 | S36: =IF(Setup!B29<>"",SUM(S7:S34),"") | T36: =IF(Setup!B30<>"",SUM(T7:T34),"") | U36: =IF(Setup!B31<>"",SUM(U7:U34),"") | V36: =IF(Setup!B32<>"",SUM(V7:V34),"") | W36: =IF(Setup!B33<>"",SUM(W7:W34),"") | X36: =IF(Setup!B34<>"",SUM(X7:X34),"") | Y36: =IF(Setup!B35<>"",SUM(Y7:Y34),"") | Z36: =IF(Setup!B36<>"",SUM(Z7:Z34),"") | AA36: =IF(Setup!B37<>"",SUM(AA7:AA34),"") | AB36: =IF(Setup!B38<>"",SUM(AB7:AB34),"") | AC36: =IF(Setup!B39<>"",SUM(AC7:AC34),"") | AD36: =IF(Setup!B40<>"",SUM(AD7:AD34),"") | AE36: =IF(Setup!B41<>"",SUM(AE7:AE34),"") | AF36: =IF(Setup!B42<>"",SUM(AF7:AF34),"") | AG36: =IF(Setup!B43<>"",SUM(AG7:AG34),"") | AH36: =IF(Setup!B44<>"",SUM(AH7:AH34),"")
A37: Absent Days (WORK days with 0 hrs) | E37: =IF(Setup!B15<>"",COUNTIFS(C7:C34,"WORK",E7:E34,0),"") -> 0 | F37: =IF(Setup!B16<>"",COUNTIFS(C7:C34,"WORK",F7:F34,0),"") -> 0 | G37: =IF(Setup!B17<>"",COUNTIFS(C7:C34,"WORK",G7:G34,0),"") -> 0 | H37: =IF(Setup!B18<>"",COUNTIFS(C7:C34,"WORK",H7:H34,0),"") -> 0 | I37: =IF(Setup!B19<>"",COUNTIFS(C7:C34,"WORK",I7:I34,0),"") -> 0 | J37: =IF(Setup!B20<>"",COUNTIFS(C7:C34,"WORK",J7:J34,0),"") -> 0 | K37: =IF(Setup!B21<>"",COUNTIFS(C7:C34,"WORK",K7:K34,0),"") -> 0 | L37: =IF(Setup!B22<>"",COUNTIFS(C7:C34,"WORK",L7:L34,0),"") -> 0 | M37: =IF(Setup!B23<>"",COUNTIFS(C7:C34,"WORK",M7:M34,0),"") -> 0 | N37: =IF(Setup!B24<>"",COUNTIFS(C7:C34,"WORK",N7:N34,0),"") -> 0 | O37: =IF(Setup!B25<>"",COUNTIFS(C7:C34,"WORK",O7:O34,0),"") -> 0 | P37: =IF(Setup!B26<>"",COUNTIFS(C7:C34,"WORK",P7:P34,0),"") -> 0 | Q37: =IF(Setup!B27<>"",COUNTIFS(C7:C34,"WORK",Q7:Q34,0),"") -> 0 | R37: =IF(Setup!B28<>"",COUNTIFS(C7:C34,"WORK",R7:R34,0),"") -> 0 | S37: =IF(Setup!B29<>"",COUNTIFS(C7:C34,"WORK",S7:S34,0),"") | T37: =IF(Setup!B30<>"",COUNTIFS(C7:C34,"WORK",T7:T34,0),"") | U37: =IF(Setup!B31<>"",COUNTIFS(C7:C34,"WORK",U7:U34,0),"") | V37: =IF(Setup!B32<>"",COUNTIFS(C7:C34,"WORK",V7:V34,0),"") | W37: =IF(Setup!B33<>"",COUNTIFS(C7:C34,"WORK",W7:W34,0),"") | X37: =IF(Setup!B34<>"",COUNTIFS(C7:C34,"WORK",X7:X34,0),"") | Y37: =IF(Setup!B35<>"",COUNTIFS(C7:C34,"WORK",Y7:Y34,0),"") | Z37: =IF(Setup!B36<>"",COUNTIFS(C7:C34,"WORK",Z7:Z34,0),"") | AA37: =IF(Setup!B37<>"",COUNTIFS(C7:C34,"WORK",AA7:AA34,0),"") | AB37: =IF(Setup!B38<>"",COUNTIFS(C7:C34,"WORK",AB7:AB34,0),"") | AC37: =IF(Setup!B39<>"",COUNTIFS(C7:C34,"WORK",AC7:AC34,0),"") | AD37: =IF(Setup!B40<>"",COUNTIFS(C7:C34,"WORK",AD7:AD34,0),"") | AE37: =IF(Setup!B41<>"",COUNTIFS(C7:C34,"WORK",AE7:AE34,0),"") | AF37: =IF(Setup!B42<>"",COUNTIFS(C7:C34,"WORK",AF7:AF34,0),"") | AG37: =IF(Setup!B43<>"",COUNTIFS(C7:C34,"WORK",AG7:AG34,0),"") | AH37: =IF(Setup!B44<>"",COUNTIFS(C7:C34,"WORK",AH7:AH34,0),"")

Sheet Attendance_Mar
A1: 📅 DAILY ATTENDANCE — MARCH 2026
A2: Month | B2: March 2026
A3: Paid Hours/Day | B3: =Setup!B8 -> 8
A4: Required Working Hours | B4: 208
A6: Date | B6: Day | C6: Type | D6: Req Hrs | E6: =Setup!B15 -> Sheraz | F6: =Setup!B16 -> Zain | G6: =Setup!B17 -> Yousaf | H6: =Setup!B18 -> Hamza | I6: =Setup!B19 -> Amjad | J6: =Setup!B20 -> Tanveer | K6: =Setup!B21 -> Ali Zaman | L6: =Setup!B22 -> Awais Ali | M6: =Setup!B23 -> Ishtiaq | N6: =Setup!B24 -> Usama bhai | O6: =Setup!B25 -> Ahtisham | P6: =Setup!B26 -> Factory rent | Q6: =Setup!B27 -> Internet bill | R6: =Setup!B28 -> Saqab | S6: =Setup!B29 -> 0 | T6: =Setup!B30 -> 0 | U6: =Setup!B31 -> 0 | V6: =Setup!B32 -> 0 | W6: =Setup!B33 -> 0 | X6: =Setup!B34 -> 0 | Y6: =Setup!B35 -> 0 | Z6: =Setup!B36 -> 0 | AA6: =Setup!B37 -> 0 | AB6: =Setup!B38 -> 0 | AC6: =Setup!B39 -> 0 | AD6: =Setup!B40 -> 0 | AE6: =Setup!B41 -> 0 | AF6: =Setup!B42 -> 0 | AG6: =Setup!B43 -> 0 | AH6: =Setup!B44 -> 0
A7: 46082 | B7: OFF | C7: OFF | D7: 0 | E7: 0 | F7: 0 | G7: 0 | H7: 0 | I7: 0 | J7: 0 | K7: 0 | L7: 0 | M7: 0 | N7: 0 | O7: 0 | P7: 0 | Q7: 0 | R7: 0 | S7: 0 | T7: 0 | U7: 0 | V7: 0 | W7: 0 | X7: 0 | Y7: 0 | Z7: 0 | AA7: 0 | AB7: 0 | AC7: 0 | AD7: 0 | AE7: 0 | AF7: 0 | AG7: 0 | AH7: 0
A8: 46083 | B8: Mon | C8: WORK | D8: 8 | E8: 8 | F8: 8 | G8: 8 | H8: 8 | I8: 8 | J8: 8 | K8: 8 | L8: 8 | M8: 7.3 | N8: 8 | O8: 8 | P8: 8 | Q8: 8
A9: 46084 | B9: Tue | C9: WORK | D9: 8 | E9: 8 | F9: 8 | G9: 8 | H9: A | I9: A | J9: 8 | K9: 8 | L9: 7.55 | M9: 3 | N9: 8 | O9: 8 | P9: 8 | Q9: 8
A10: 46085 | B10: Wed | C10: WORK | D10: 8 | E10: A | F10: 8 | G10: 8 | H10: 8 | I10: 8 | J10: 8 | K10: 8 | L10: 8 | M10: 4 | N10: 8 | O10: 8 | P10: 8 | Q10: 8
A11: 46086 | B11: Thu | C11: WORK | D11: 8 | E11: 8 | F11: 8 | G11: 8 | H11: 8.3 | I11: 8 | J11: 8 | K11: 8 | L11: 7.45 | M11: 7.5 | N11: 8 | O11: 8 | P11: 8 | Q11: 8
A12: 46087 | B12: Fri | C12: WORK | D12: 8 | E12: 8 | F12: 8 | G12: 8 | H12: 8 | I12: 8 | J12: 8 | K12: 8 | L12: 8 | M12: 2 | N12: 8 | O12: 8 | P12: 8 | Q12: 8
A13: 46088 | B13: Sat | C13: WORK | D13: 8 | E13: 8 | F13: 8 | G13: 8 | H13: 9.3 | I13: 8 | J13: 8 | K13: 8 | L13: 8 | M13: A | N13: 8 | O13: 8 | P13: 8 | Q13: 8
A14: 46089 | B14: OFF | C14: OFF | D14: 0 | E14: 0 | F14: 0 | G14: 0 | H14: 0 | I14: 0 | J14: 0 | K14: 0 | L14: 0 | M14: 0 | N14: 0 | O14: 0 | P14: 0 | Q14: 0 | R14: 0 | S14: 0 | T14: 0 | U14: 0 | V14: 0 | W14: 0 | X14: 0 | Y14: 0 | Z14: 0 | AA14: 0 | AB14: 0 | AC14: 0 | AD14: 0 | AE14: 0 | AF14: 0 | AG14: 0 | AH14: 0
A15: 46090 | B15: Mon | C15: WORK | D15: 8 | E15: 8 | F15: 8 | G15: 8 | H15: 8 | I15: 8 | J15: 8 | K15: 8 | L15: 8 | M15: 8 | N15: 8 | O15: 8 | P15: 8 | Q15: 8
A16: 46091 | B16: Tue | C16: WORK | D16: 8 | E16: 8 | F16: 8 | G16: 8 | H16: A | I16: 8 | J16: 8 | K16: 8 | L16: 8 | M16: 8 | N16: 8 | O16: 8 | P16: 8 | Q16: 8
A17: 46092 | B17: Wed | C17: WORK | D17: 8 | E17: 5 | F17: 8 | G17: A | H17: 8 | I17: 8 | J17: 8 | K17: 8 | L17: 7.55 | M17: 7.5 | N17: 8 | O17: 8 | P17: 8 | Q17: 8
A18: 46093 | B18: Thu | C18: WORK | D18: 8 | E18: 8 | F18: 8 | G18: 8 | H18: 7.4 | I18: 8 | J18: 8 | K18: 8 | L18: 8 | M18: 7.5 | N18: 8 | O18: 8 | P18: 8 | Q18: 8
A19: 46094 | B19: Fri | C19: WORK | D19: 8 | E19: 8 | F19: 8 | G19: 8 | H19: 7.5 | I19: 5.1 | J19: 8 | K19: 8 | L19: 7.55 | M19: 8 | N19: 8 | O19: 8 | P19: 8 | Q19: 8
A20: 46095 | B20: Sat | C20: WORK | D20: 8 | E20: 8 | F20: 8 | G20: 8 | H20: 7.45 | I20: 8 | J20: 8 | K20: 8 | L20: 5 | M20: 7.45 | N20: 8 | O20: 8 | P20: 8 | Q20: 8
A21: 46096 | B21: OFF | C21: OFF | D21: 0 | E21: 0 | F21: 0 | G21: 0 | H21: 0 | I21: 0 | J21: 0 | K21: 0 | L21: 0 | M21: 0 | N21: 0 | O21: 0 | P21: 0 | Q21: 0 | R21: 0 | S21: 0 | T21: 0 | U21: 0 | V21: 0 | W21: 0 | X21: 0 | Y21: 0 | Z21: 0 | AA21: 0 | AB21: 0 | AC21: 0 | AD21: 0 | AE21: 0 | AF21: 0 | AG21: 0 | AH21: 0
A22: 46097 | B22: Mon | C22: WORK | D22: 8 | E22: 7.3 | F22: A | G22: A | H22: 7.45 | I22: 7.53 | J22: 8 | K22: 8 | L22: 7.2 | M22: A | N22: 8 | O22: 8 | P22: 8 | Q22: 8
A23: 46098 | B23: Tue | C23: WORK | D23: 8 | E23: 7.55 | F23: 8 | G23: A | H23: 8 | I23: 8.55 | J23: 8 | K23: 8 | L23: A | M23: 8 | N23: 8 | O23: 8 | P23: 8 | Q23: 8
A24: 46099 | B24: Wed | C24: WORK | D24: 8 | E24: 8 | F24: 8 | G24: 8 | H24: 8 | I24: 8 | J24: 8 | K24: 8 | L24: A | M24: 8 | N24: 8 | O24: 8 | P24: 8 | Q24: 8
A25: 46100 | B25: Thu | C25: WORK | D25: 8 | E25: 5.45 | F25: 6 | G25: 6 | H25: 6 | I25: 6 | J25: 8 | K25: 8 | L25: 6 | M25: 6 | N25: 8 | O25: 8 | P25: 8 | Q25: 8
A26: 46101 | B26: Fri | C26: WORK | D26: 8 | E26: 8 | F26: 8 | G26: 8 | H26: 8 | I26: 8 | J26: 8 | K26: 8 | L26: 8 | M26: 8 | N26: 8 | O26: 8 | P26: 8 | Q26: 8
A27: 46102 | B27: Sat | C27: WORK | D27: 8 | E27: 8 | F27: 8 | G27: 8 | H27: 8 | I27: 8 | J27: 8 | K27: 8 | L27: 8 | M27: 8 | N27: 8 | O27: 8 | P27: 8 | Q27: 8
A28: 46103 | B28: OFF | C28: OFF | D28: 0 | E28: 0 | F28: 0 | G28: 0 | H28: 0 | I28: 0 | J28: 0 | K28: 0 | L28: 0 | M28: 0 | N28: 0 | O28: 0 | P28: 0 | Q28: 0 | R28: 0 | S28: 0 | T28: 0 | U28: 0 | V28: 0 | W28: 0 | X28: 0 | Y28: 0 | Z28: 0 | AA28: 0 | AB28: 0 | AC28: 0 | AD28: 0 | AE28: 0 | AF28: 0 | AG28: 0 | AH28: 0
A29: 46104 | B29: Mon | C29: WORK | D29: 8 | E29: 8 | F29: 8 | G29: 8 | H29: 8 | I29: 8 | J29: 8 | K29: 8 | L29: 8 | M29: 8 | N29: 8 | O29: 8 | P29: 8 | Q29: 8
A30: 46105 | B30: Tue | C30: WORK | D30: 8 | E30: A | F30: 7 | G30: 3 | H30: 6.5 | I30: A | J30: 8 | K30: 8 | L30: 7.4 | M30: 5 | N30: 8 | O30: 8 | P30: 8 | Q30: 8
A31: 46106 | B31: Wed | C31: WORK | D31: 8 | E31: A | F31: 8 | G31: 8 | H31: A | I31: 8 | J31: 8 | K31: 8 | L31: 5 | M31: 4 | N31: 8 | O31: 8 | P31: 8 | Q31: 8
A32: 46107 | B32: Thu | C32: WORK | D32: 8 | E32: A | F32: 8 | G32: 8 | H32: 7.4 | I32: 8 | J32: 8 | K32: 8 | L32: A | M32: 5 | N32: 8 | O32: 8 | P32: 8 | Q32: 8
A33: 46108 | B33: Fri | C33: WORK | D33: 8 | E33: 7 | F33: 8 | G33: A | H33: 8 | I33: 8 | J33: 8 | K33: 8 | L33: 7.38 | M33: 7.3 | N33: 8 | O33: 8 | P33: 8 | Q33: 8
A34: 46109 | B34: Sat | C34: WORK | D34: 8 | E34: A | F34: 8 | G34: 8 | H34: 7.52 | I34: A | J34: 8 | K34: 8 | L34: 7.52 | M34: 7.45 | N34: 8 | O34: 8 | P34: 8 | Q34: 8
A35: 46110 | B35: OFF | C35: OFF | D35: 0 | E35: 0 | F35: 0 | G35: 0 | H35: 0 | I35: 0 | J35: 0 | K35: 0 | L35: 0 | M35: 0 | N35: 0 | O35: 0 | P35: 0 | Q35: 0 | R35: 0 | S35: 0 | T35: 0 | U35: 0 | V35: 0 | W35: 0 | X35: 0 | Y35: 0 | Z35: 0 | AA35: 0 | AB35: 0 | AC35: 0 | AD35: 0 | AE35: 0 | AF35: 0 | AG35: 0 | AH35: 0
A36: 46111 | B36: Mon | C36: WORK | D36: 8 | E36: 8 | F36: 8 | G36: A | H36: 4.5 | I36: 8 | J36: 8 | K36: 8 | L36: 7.55 | M36: 7.55 | N36: 8 | O36: 8 | P36: 8 | Q36: 8
A37: 46112 | B37: Tue | C37: WORK | D37: 8 | E37: 8 | F37: 8 | G37: 8 | H37: 8 | I37: 8 | J37: 8 | K37: 8 | L37: 7.48 | M37: 5 | N37: 8 | O37: 8 | P37: 8 | Q37: 8
A39: TOTALS | E39: =IF(Setup!B15<>"",SUM(E7:E37),"") -> 160.3 | F39: =IF(Setup!B16<>"",SUM(F7:F37),"") -> 197 | G39: =IF(Setup!B17<>"",SUM(G7:G37),"") -> 161 | H39: =IF(Setup!B18<>"",SUM(H7:H37),"") -> 175.32 | I39: =IF(Setup!B19<>"",SUM(I7:I37),"") -> 179.18 | J39: =IF(Setup!B20<>"",SUM(J7:J37),"") -> 208 | K39: =IF(Setup!B21<>"",SUM(K7:K37),"") -> 208 | L39: =IF(Setup!B22<>"",SUM(L7:L37),"") -> 170.63 | M39: =IF(Setup!B23<>"",SUM(M7:M37),"") -> 157.55 | N39: =IF(Setup!B24<>"",SUM(N7:N37),"") -> 208 | O39: =IF(Setup!B25<>"",SUM(O7:O37),"") -> 208 | P39: =IF(Setup!B26<>"",SUM(P7:P37),"") -> 208 | Q39: =IF(Setup!B27<>"",SUM(Q7:Q37),"") -> 208 | R39: =IF(Setup!B28<>"",SUM(R7:R37),"") -> 0 | S39: =IF(Setup!B29<>"",SUM(S7:S37),"") | T39: =IF(Setup!B30<>"",SUM(T7:T37),"") | U39: =IF(Setup!B31<>"",SUM(U7:U37),"") | V39: =IF(Setup!B32<>"",SUM(V7:V37),"") | W39: =IF(Setup!B33<>"",SUM(W7:W37),"") | X39: =IF(Setup!B34<>"",SUM(X7:X37),"") | Y39: =IF(Setup!B35<>"",SUM(Y7:Y37),"") | Z39: =IF(Setup!B36<>"",SUM(Z7:Z37),"") | AA39: =IF(Setup!B37<>"",SUM(AA7:AA37),"") | AB39: =IF(Setup!B38<>"",SUM(AB7:AB37),"") | AC39: =IF(Setup!B39<>"",SUM(AC7:AC37),"") | AD39: =IF(Setup!B40<>"",SUM(AD7:AD37),"") | AE39: =IF(Setup!B41<>"",SUM(AE7:AE37),"") | AF39: =IF(Setup!B42<>"",SUM(AF7:AF37),"") | AG39: =IF(Setup!B43<>"",SUM(AG7:AG37),"") | AH39: =IF(Setup!B44<>"",SUM(AH7:AH37),"")
A40: Absent Days (WORK days with 0 hrs) | E40: =IF(Setup!B15<>"",COUNTIFS(C7:C37,"WORK",E7:E37,0),"") -> 0 | F40: =IF(Setup!B16<>"",COUNTIFS(C7:C37,"WORK",F7:F37,0),"") -> 0 | G40: =IF(Setup!B17<>"",COUNTIFS(C7:C37,"WORK",G7:G37,0),"") -> 0 | H40: =IF(Setup!B18<>"",COUNTIFS(C7:C37,"WORK",H7:H37,0),"") -> 0 | I40: =IF(Setup!B19<>"",COUNTIFS(C7:C37,"WORK",I7:I37,0),"") -> 0 | J40: =IF(Setup!B20<>"",COUNTIFS(C7:C37,"WORK",J7:J37,0),"") -> 0 | K40: =IF(Setup!B21<>"",COUNTIFS(C7:C37,"WORK",K7:K37,0),"") -> 0 | L40: =IF(Setup!B22<>"",COUNTIFS(C7:C37,"WORK",L7:L37,0),"") -> 0 | M40: =IF(Setup!B23<>"",COUNTIFS(C7:C37,"WORK",M7:M37,0),"") -> 0 | N40: =IF(Setup!B24<>"",COUNTIFS(C7:C37,"WORK",N7:N37,0),"") -> 0 | O40: =IF(Setup!B25<>"",COUNTIFS(C7:C37,"WORK",O7:O37,0),"") -> 0 | P40: =IF(Setup!B26<>"",COUNTIFS(C7:C37,"WORK",P7:P37,0),"") -> 0 | Q40: =IF(Setup!B27<>"",COUNTIFS(C7:C37,"WORK",Q7:Q37,0),"") -> 0 | R40: =IF(Setup!B28<>"",COUNTIFS(C7:C37,"WORK",R7:R37,0),"") -> 0 | S40: =IF(Setup!B29<>"",COUNTIFS(C7:C37,"WORK",S7:S37,0),"") | T40: =IF(Setup!B30<>"",COUNTIFS(C7:C37,"WORK",T7:T37,0),"") | U40: =IF(Setup!B31<>"",COUNTIFS(C7:C37,"WORK",U7:U37,0),"") | V40: =IF(Setup!B32<>"",COUNTIFS(C7:C37,"WORK",V7:V37,0),"") | W40: =IF(Setup!B33<>"",COUNTIFS(C7:C37,"WORK",W7:W37,0),"") | X40: =IF(Setup!B34<>"",COUNTIFS(C7:C37,"WORK",X7:X37,0),"") | Y40: =IF(Setup!B35<>"",COUNTIFS(C7:C37,"WORK",Y7:Y37,0),"") | Z40: =IF(Setup!B36<>"",COUNTIFS(C7:C37,"WORK",Z7:Z37,0),"") | AA40: =IF(Setup!B37<>"",COUNTIFS(C7:C37,"WORK",AA7:AA37,0),"") | AB40: =IF(Setup!B38<>"",COUNTIFS(C7:C37,"WORK",AB7:AB37,0),"") | AC40: =IF(Setup!B39<>"",COUNTIFS(C7:C37,"WORK",AC7:AC37,0),"") | AD40: =IF(Setup!B40<>"",COUNTIFS(C7:C37,"WORK",AD7:AD37,0),"") | AE40: =IF(Setup!B41<>"",COUNTIFS(C7:C37,"WORK",AE7:AE37,0),"") | AF40: =IF(Setup!B42<>"",COUNTIFS(C7:C37,"WORK",AF7:AF37,0),"") | AG40: =IF(Setup!B43<>"",COUNTIFS(C7:C37,"WORK",AG7:AG37,0),"") | AH40: =IF(Setup!B44<>"",COUNTIFS(C7:C37,"WORK",AH7:AH37,0),"")

Sheet Attendance_Apr
A1: 📅 DAILY ATTENDANCE — APRIL 2026
A2: Month | B2: April 2026
A3: Paid Hours/Day | B3: =Setup!B8 -> 8
A4: Required Working Hours | B4: 208
A6: Date | B6: Day | C6: Type | D6: Req Hrs | E6: =Setup!B15 -> Sheraz | F6: =Setup!B16 -> Zain | G6: =Setup!B17 -> Yousaf | H6: =Setup!B18 -> Hamza | I6: =Setup!B19 -> Amjad | J6: =Setup!B20 -> Tanveer | K6: =Setup!B21 -> Ali Zaman | L6: =Setup!B22 -> Awais Ali | M6: =Setup!B23 -> Ishtiaq | N6: =Setup!B24 -> Usama bhai | O6: =Setup!B25 -> Ahtisham | P6: =Setup!B26 -> Factory rent | Q6: =Setup!B27 -> Internet bill | R6: =Setup!B28 -> Saqab | S6: =Setup!B29 -> 0 | T6: =Setup!B30 -> 0 | U6: =Setup!B31 -> 0 | V6: =Setup!B32 -> 0 | W6: =Setup!B33 -> 0 | X6: =Setup!B34 -> 0 | Y6: =Setup!B35 -> 0 | Z6: =Setup!B36 -> 0 | AA6: =Setup!B37 -> 0 | AB6: =Setup!B38 -> 0 | AC6: =Setup!B39 -> 0 | AD6: =Setup!B40 -> 0 | AE6: =Setup!B41 -> 0 | AF6: =Setup!B42 -> 0 | AG6: =Setup!B43 -> 0 | AH6: =Setup!B44 -> 0
A7: 46113 | B7: Wed | C7: WORK | D7: 8 | E7: 8 | F7: 8 | G7: 8 | H7: 5 | I7: 7.48 | J7: 8 | K7: 8 | L7: 7.5 | M7: 7.55 | N7: 8 | O7: 8 | P7: 8 | Q7: 8
A8: 46114 | B8: Thu | C8: WORK | D8: 8 | E8: 7.55 | F8: 8 | G8: 8 | H8: 9 | I8: 7.45 | J8: 8 | K8: 8 | L8: 9 | M8: 7.55 | N8: 8 | O8: 8 | P8: 8 | Q8: 8
A9: 46115 | B9: Fri | C9: WORK | D9: 8 | E9: 8 | F9: 8 | G9: 8 | H9: 7.5 | I9: 7.52 | J9: 8 | K9: 8 | L9: 8 | M9: 7.5 | N9: 8 | O9: 8 | P9: 8 | Q9: 8
A10: 46116 | B10: Sat | C10: WORK | D10: 8 | E10: 8 | F10: 8 | G10: 8 | H10: 7.5 | I10: 5.43 | J10: 8 | K10: 8 | L10: 7.5 | M10: 8 | N10: 8 | O10: 8 | P10: 8 | Q10: 8
A11: 46117 | B11: OFF | C11: OFF | D11: 0 | E11: 0 | F11: 8 | G11: 0 | H11: 0 | I11: 0 | J11: 0 | K11: 0 | L11: 0 | M11: 0 | N11: 0 | O11: 0 | P11: 0 | Q11: 0 | R11: 0 | S11: 0 | T11: 0 | U11: 0 | V11: 0 | W11: 0 | X11: 0 | Y11: 0 | Z11: 0 | AA11: 0 | AB11: 0 | AC11: 0 | AD11: 0 | AE11: 0 | AF11: 0 | AG11: 0 | AH11: 0
A12: 46118 | B12: Mon | C12: WORK | D12: 8 | E12: 8 | F12: 7.5 | G12: A | H12: 8 | I12: 7.5 | J12: 8 | K12: 8 | L12: A | M12: 8 | N12: 8 | O12: 8 | P12: 8 | Q12: 8
A13: 46119 | B13: Tue | C13: WORK | D13: 8 | E13: A | F13: 8 | G13: 8 | H13: 8 | I13: 7.4 | J13: 8 | K13: 8 | L13: 8 | M13: 8 | N13: 8 | O13: 8 | P13: 8 | Q13: 8
A14: 46120 | B14: Wed | C14: WORK | D14: 8 | E14: 8 | F14: 7.4 | G14: 10 | H14: 5 | I14: 8 | J14: 8 | K14: 8 | L14: 7.5 | M14: 7.42 | N14: 8 | O14: 8 | P14: 8 | Q14: 8
A15: 46121 | B15: Thu | C15: WORK | D15: 8 | E15: 8 | F15: 8 | G15: 8 | H15: 7.45 | I15: 8 | J15: 8 | K15: 8 | L15: 7.3 | M15: 8 | N15: 8 | O15: 8 | P15: 8 | Q15: 8
A16: 46122 | B16: Fri | C16: WORK | D16: 8 | E16: 8 | F16: 8 | G16: 8 | H16: 7.45 | I16: 8 | J16: 8 | K16: 8 | L16: 8 | M16: 8 | N16: 8 | O16: 8 | P16: 8 | Q16: 8
A17: 46123 | B17: Sat | C17: WORK | D17: 8 | E17: 8 | F17: 8 | G17: 8 | H17: 7.43 | I17: 7.5 | J17: A | K17: 8 | L17: 15.5 | M17: A | N17: 8 | O17: 8 | P17: 8 | Q17: 8
A18: 46124 | B18: OFF | C18: OFF | D18: 0 | E18: 0 | F18: 0 | G18: 0 | H18: 0 | I18: 0 | J18: 0 | K18: 0 | L18: 0 | M18: 0 | N18: 0 | O18: 0 | P18: 0 | Q18: 0 | R18: 0 | S18: 0 | T18: 0 | U18: 0 | V18: 0 | W18: 0 | X18: 0 | Y18: 0 | Z18: 0 | AA18: 0 | AB18: 0 | AC18: 0 | AD18: 0 | AE18: 0 | AF18: 0 | AG18: 0 | AH18: 0
A19: 46125 | B19: Mon | C19: WORK | D19: 8 | E19: 7.55 | F19: 8 | G19: 8 | H19: 8 | I19: 8 | J19: A | K19: 8 | L19: A | M19: 15.55 | N19: 8 | O19: 8 | P19: 8 | Q19: 8
A20: 46126 | B20: Tue | C20: WORK | D20: 8 | E20: 8 | F20: 8 | G20: 8 | H20: 8 | I20: 8 | J20: A | K20: 8 | L20: 8 | M20: 16 | N20: 8 | O20: 8 | P20: 8 | Q20: 8
A21: 46127 | B21: Wed | C21: WORK | D21: 8 | E21: 8 | F21: 8 | G21: 8 | H21: 8 | I21: A | J21: 8 | K21: 8 | L21: 7.5 | M21: 8 | N21: 8 | O21: 8 | P21: 8 | Q21: 8
A22: 46128 | B22: Thu | C22: WORK | D22: 8 | E22: A | F22: 8 | G22: 8 | H22: 8 | I22: 8 | J22: 8 | K22: 8 | L22: 7.45 | M22: 8 | N22: 8 | O22: 8 | P22: 8 | Q22: 8
A23: 46129 | B23: Fri | C23: WORK | D23: 8 | E23: 7.5 | F23: 8 | G23: 8 | H23: A | I23: 7.4 | J23: 8 | K23: 8 | L23: 7.5 | M23: A | N23: 8 | O23: 8 | P23: 8 | Q23: 8
A24: 46130 | B24: Sat | C24: WORK | D24: 8 | E24: 8 | F24: 8 | G24: 8 | H24: 7.55 | I24: 7.55 | J24: 8 | K24: 8 | L24: 7.5 | M24: 8 | N24: 8 | O24: 8 | P24: 8 | Q24: 8
A25: 46131 | B25: OFF | C25: OFF | D25: 0 | E25: 0 | F25: 0 | G25: 0 | H25: 0 | I25: 7.5 | J25: 0 | K25: 0 | L25: 0 | M25: 0 | N25: 0 | O25: 0 | P25: 0 | Q25: 0 | R25: 0 | S25: 0 | T25: 0 | U25: 0 | V25: 0 | W25: 0 | X25: 0 | Y25: 0 | Z25: 0 | AA25: 0 | AB25: 0 | AC25: 0 | AD25: 0 | AE25: 0 | AF25: 0 | AG25: 0 | AH25: 0
A26: 46132 | B26: Mon | C26: WORK | D26: 8 | E26: 8 | F26: 8 | G26: 8 | H26: A | I26: 7.5 | J26: 8 | K26: 8 | L26: 7.5 | M26: 8 | N26: 8 | O26: 8 | P26: 8 | Q26: 8
A27: 46133 | B27: Tue | C27: WORK | D27: 8 | E27: 8 | F27: 8 | G27: 8 | H27: A | I27: 8 | J27: 8 | K27: 8 | L27: 7.5 | M27: 5 | N27: 8 | O27: 8 | P27: 8 | Q27: 8
A28: 46134 | B28: Wed | C28: WORK | D28: 8 | E28: 8 | F28: 8 | G28: A | H28: A | I28: 8 | J28: 8 | K28: 8 | L28: 8 | M28: 8 | N28: 8 | O28: 8 | P28: 8 | Q28: 8
A29: 46135 | B29: Thu | C29: WORK | D29: 8 | E29: 8 | F29: 8 | G29: 8 | H29: 8 | I29: 7.45 | J29: A | K29: 8 | L29: 8 | M29: 15.4 | N29: 8 | O29: 8 | P29: 8 | Q29: 8
A30: 46136 | B30: Fri | C30: WORK | D30: 8 | E30: 8 | F30: 8 | G30: 5 | H30: 8 | I30: 8 | J30: A | K30: 8 | L30: 8 | M30: 16 | N30: 8 | O30: 8 | P30: 8 | Q30: 8
A31: 46137 | B31: Sat | C31: WORK | D31: 8 | E31: 7.45 | F31: 8 | G31: 8 | H31: 9 | I31: 7.5 | J31: 8 | K31: 8 | L31: 7.5 | M31: 8 | N31: 8 | O31: 8 | P31: 8 | Q31: 8
A32: 46138 | B32: OFF | C32: OFF | D32: 0 | E32: 0 | F32: 0 | G32: 0 | H32: 0 | I32: 0 | J32: 0 | K32: 0 | L32: 0 | M32: 0 | N32: 0 | O32: 0 | P32: 0 | Q32: 0 | R32: 0 | S32: 0 | T32: 0 | U32: 0 | V32: 0 | W32: 0 | X32: 0 | Y32: 0 | Z32: 0 | AA32: 0 | AB32: 0 | AC32: 0 | AD32: 0 | AE32: 0 | AF32: 0 | AG32: 0 | AH32: 0
A33: 46139 | B33: Mon | C33: WORK | D33: 8 | E33: 6.2 | F33: 8 | G33: 8 | H33: 7.3 | I33: A | J33: 8 | K33: 8 | L33: 8 | M33: 7.5 | N33: 8 | O33: 8 | P33: 8 | Q33: 8
A34: 46140 | B34: Tue | C34: WORK | D34: 8 | E34: 7.5 | F34: 8 | G34: 8 | H34: 8 | I34: 8 | J34: 8 | K34: 8 | L34: 8 | M34: A | N34: 8 | O34: 8 | P34: 8 | Q34: 8
A35: 46141 | B35: Wed | C35: WORK | D35: 8 | E35: 7.3 | F35: 8 | G35: 8 | H35: 8.5 | I35: 7.5 | J35: 8 | K35: 8 | L35: 8 | M35: 8 | N35: 8 | O35: 8 | P35: 8 | Q35: 8
A36: 46142 | B36: Thu | C36: WORK | D36: 8 | E36: 8 | F36: 8 | G36: 8 | H36: 8 | I36: 7.4 | J36: 8 | K36: 8 | L36: 7.45 | M36: 8 | N36: 8 | O36: 8 | P36: 8 | Q36: 8
A38: TOTALS | E38: =IF(Setup!B15<>"",SUM(E7:E36),"") -> 187.05 | F38: =IF(Setup!B16<>"",SUM(F7:F36),"") -> 214.9 | G38: =IF(Setup!B17<>"",SUM(G7:G36),"") -> 191 | H38: =IF(Setup!B18<>"",SUM(H7:H36),"") -> 168.68 | I38: =IF(Setup!B19<>"",SUM(I7:I36),"") -> 190.08 | J38: =IF(Setup!B20<>"",SUM(J7:J36),"") -> 168 | K38: =IF(Setup!B21<>"",SUM(K7:K36),"") -> 208 | L38: =IF(Setup!B22<>"",SUM(L7:L36),"") -> 194.2 | M38: =IF(Setup!B23<>"",SUM(M7:M36),"") -> 209.47 | N38: =IF(Setup!B24<>"",SUM(N7:N36),"") -> 208 | O38: =IF(Setup!B25<>"",SUM(O7:O36),"") -> 208 | P38: =IF(Setup!B26<>"",SUM(P7:P36),"") -> 208 | Q38: =IF(Setup!B27<>"",SUM(Q7:Q36),"") -> 208 | R38: =IF(Setup!B28<>"",SUM(R7:R36),"") -> 0 | S38: =IF(Setup!B29<>"",SUM(S7:S36),"") | T38: =IF(Setup!B30<>"",SUM(T7:T36),"") | U38: =IF(Setup!B31<>"",SUM(U7:U36),"") | V38: =IF(Setup!B32<>"",SUM(V7:V36),"") | W38: =IF(Setup!B33<>"",SUM(W7:W36),"") | X38: =IF(Setup!B34<>"",SUM(X7:X36),"") | Y38: =IF(Setup!B35<>"",SUM(Y7:Y36),"") | Z38: =IF(Setup!B36<>"",SUM(Z7:Z36),"") | AA38: =IF(Setup!B37<>"",SUM(AA7:AA36),"") | AB38: =IF(Setup!B38<>"",SUM(AB7:AB36),"") | AC38: =IF(Setup!B39<>"",SUM(AC7:AC36),"") | AD38: =IF(Setup!B40<>"",SUM(AD7:AD36),"") | AE38: =IF(Setup!B41<>"",SUM(AE7:AE36),"") | AF38: =IF(Setup!B42<>"",SUM(AF7:AF36),"") | AG38: =IF(Setup!B43<>"",SUM(AG7:AG36),"") | AH38: =IF(Setup!B44<>"",SUM(AH7:AH36),"")
A39: Absent Days (WORK days with 0 hrs) | E39: =IF(Setup!B15<>"",COUNTIFS(C7:C36,"WORK",E7:E36,0),"") -> 0 | F39: =IF(Setup!B16<>"",COUNTIFS(C7:C36,"WORK",F7:F36,0),"") -> 0 | G39: =IF(Setup!B17<>"",COUNTIFS(C7:C36,"WORK",G7:G36,0),"") -> 0 | H39: =IF(Setup!B18<>"",COUNTIFS(C7:C36,"WORK",H7:H36,0),"") -> 0 | I39: =IF(Setup!B19<>"",COUNTIFS(C7:C36,"WORK",I7:I36,0),"") -> 0 | J39: =IF(Setup!B20<>"",COUNTIFS(C7:C36,"WORK",J7:J36,0),"") -> 0 | K39: =IF(Setup!B21<>"",COUNTIFS(C7:C36,"WORK",K7:K36,0),"") -> 0 | L39: =IF(Setup!B22<>"",COUNTIFS(C7:C36,"WORK",L7:L36,0),"") -> 0 | M39: =IF(Setup!B23<>"",COUNTIFS(C7:C36,"WORK",M7:M36,0),"") -> 0 | N39: =IF(Setup!B24<>"",COUNTIFS(C7:C36,"WORK",N7:N36,0),"") -> 0 | O39: =IF(Setup!B25<>"",COUNTIFS(C7:C36,"WORK",O7:O36,0),"") -> 0 | P39: =IF(Setup!B26<>"",COUNTIFS(C7:C36,"WORK",P7:P36,0),"") -> 0 | Q39: =IF(Setup!B27<>"",COUNTIFS(C7:C36,"WORK",Q7:Q36,0),"") -> 0 | R39: =IF(Setup!B28<>"",COUNTIFS(C7:C36,"WORK",R7:R36,0),"") -> 0 | S39: =IF(Setup!B29<>"",COUNTIFS(C7:C36,"WORK",S7:S36,0),"") | T39: =IF(Setup!B30<>"",COUNTIFS(C7:C36,"WORK",T7:T36,0),"") | U39: =IF(Setup!B31<>"",COUNTIFS(C7:C36,"WORK",U7:U36,0),"") | V39: =IF(Setup!B32<>"",COUNTIFS(C7:C36,"WORK",V7:V36,0),"") | W39: =IF(Setup!B33<>"",COUNTIFS(C7:C36,"WORK",W7:W36,0),"") | X39: =IF(Setup!B34<>"",COUNTIFS(C7:C36,"WORK",X7:X36,0),"") | Y39: =IF(Setup!B35<>"",COUNTIFS(C7:C36,"WORK",Y7:Y36,0),"") | Z39: =IF(Setup!B36<>"",COUNTIFS(C7:C36,"WORK",Z7:Z36,0),"") | AA39: =IF(Setup!B37<>"",COUNTIFS(C7:C36,"WORK",AA7:AA36,0),"") | AB39: =IF(Setup!B38<>"",COUNTIFS(C7:C36,"WORK",AB7:AB36,0),"") | AC39: =IF(Setup!B39<>"",COUNTIFS(C7:C36,"WORK",AC7:AC36,0),"") | AD39: =IF(Setup!B40<>"",COUNTIFS(C7:C36,"WORK",AD7:AD36,0),"") | AE39: =IF(Setup!B41<>"",COUNTIFS(C7:C36,"WORK",AE7:AE36,0),"") | AF39: =IF(Setup!B42<>"",COUNTIFS(C7:C36,"WORK",AF7:AF36,0),"") | AG39: =IF(Setup!B43<>"",COUNTIFS(C7:C36,"WORK",AG7:AG36,0),"") | AH39: =IF(Setup!B44<>"",COUNTIFS(C7:C36,"WORK",AH7:AH36,0),"")

Sheet Attendance_May
A1: 📅 DAILY ATTENDANCE — MAY 2026
A2: Month | B2: May 2026
A3: Paid Hours/Day | B3: =Setup!B8 -> 8
A4: Required Working Hours | B4: 208
A6: Date | B6: Day | C6: Type | D6: Req Hrs | E6: =Setup!B15 -> Sheraz | F6: =Setup!B16 -> Zain | G6: =Setup!B17 -> Yousaf | H6: =Setup!B18 -> Hamza | I6: =Setup!B19 -> Amjad | J6: =Setup!B20 -> Tanveer | K6: =Setup!B21 -> Ali Zaman | L6: =Setup!B22 -> Awais Ali | M6: =Setup!B23 -> Ishtiaq | N6: =Setup!B24 -> Usama bhai | O6: =Setup!B25 -> Ahtisham | P6: =Setup!B26 -> Factory rent | Q6: =Setup!B27 -> Internet bill | R6: =Setup!B28 -> Saqab | S6: =Setup!B29 -> 0 | T6: =Setup!B30 -> 0 | U6: =Setup!B31 -> 0 | V6: =Setup!B32 -> 0 | W6: =Setup!B33 -> 0 | X6: =Setup!B34 -> 0 | Y6: =Setup!B35 -> 0 | Z6: =Setup!B36 -> 0 | AA6: =Setup!B37 -> 0 | AB6: =Setup!B38 -> 0 | AC6: =Setup!B39 -> 0 | AD6: =Setup!B40 -> 0 | AE6: =Setup!B41 -> 0 | AF6: =Setup!B42 -> 0 | AG6: =Setup!B43 -> 0 | AH6: =Setup!B44 -> 0
A7: 46143 | B7: Fri | C7: WORK | D7: 8 | E7: 8 | F7: 8 | G7: 8 | H7: 8 | I7: 8 | J7: 8 | K7: 8 | L7: 8 | M7: 8 | N7: 8 | P7: 8 | Q7: 8
A8: 46144 | B8: Sat | C8: WORK | D8: 8 | E8: 8 | F8: 8 | G8: 8 | H8: 8 | I8: 7.5 | J8: 8 | K8: 8 | L8: 8 | M8: A | N8: 8 | P8: 8 | Q8: 8
A9: 46145 | B9: OFF | C9: OFF | D9: 0 | E9: 8 | F9: 0 | G9: 0 | H9: 0 | I9: 0 | J9: 0 | K9: 0 | L9: 0 | M9: 0 | N9: 0 | O9: 0 | P9: 0 | Q9: 0 | R9: 0 | S9: 0 | T9: 0 | U9: 0 | V9: 0 | W9: 0 | X9: 0 | Y9: 0 | Z9: 0 | AA9: 0 | AB9: 0 | AC9: 0 | AD9: 0 | AE9: 0 | AF9: 0 | AG9: 0 | AH9: 0
A10: 46146 | B10: Mon | C10: WORK | D10: 8 | E10: 8 | F10: 8 | G10: 8 | H10: 8 | I10: 8 | J10: 8 | K10: 8 | L10: 8 | M10: A | N10: 8 | P10: 8 | Q10: 8
A11: 46147 | B11: Tue | C11: WORK | D11: 8 | E11: 8 | F11: 8 | G11: 8 | H11: 8 | I11: 8 | J11: 8 | K11: 8 | L11: 8 | M11: A | N11: 8 | P11: 8 | Q11: 8
A12: 46148 | B12: Wed | C12: WORK | D12: 8 | E12: 8 | F12: 8 | G12: 8 | H12: 8 | I12: 8 | J12: 8 | K12: 8 | L12: 8 | M12: 8 | N12: 8 | P12: 8 | Q12: 8
A13: 46149 | B13: Thu | C13: WORK | D13: 8 | E13: 7.5 | F13: 8 | G13: 8 | H13: 8 | I13: 7.5 | J13: 8 | K13: 8 | L13: 7.5 | M13: 8 | N13: 8 | P13: 8 | Q13: 8
A14: 46150 | B14: Fri | C14: WORK | D14: 8 | E14: 7.45 | F14: 8 | G14: 8 | H14: 8 | I14: 5 | J14: 8 | K14: 8 | L14: 7.35 | M14: 8 | N14: 8 | P14: 8 | Q14: 8
A15: 46151 | B15: Sat | C15: WORK | D15: 8 | E15: 7.45 | F15: 8 | G15: 8 | H15: 5 | I15: 8 | J15: 8 | K15: 8 | L15: 7.45 | M15: 8 | N15: 8 | P15: 8 | Q15: 8
A16: 46152 | B16: OFF | C16: OFF | D16: 0 | E16: 0 | F16: 0 | G16: 0 | H16: 0 | I16: 0 | J16: 0 | K16: 0 | L16: 0 | M16: 0 | N16: 0 | O16: 0 | P16: 0 | Q16: 0 | R16: 0 | S16: 0 | T16: 0 | U16: 0 | V16: 0 | W16: 0 | X16: 0 | Y16: 0 | Z16: 0 | AA16: 0 | AB16: 0 | AC16: 0 | AD16: 0 | AE16: 0 | AF16: 0 | AG16: 0 | AH16: 0
A17: 46153 | B17: Mon | C17: WORK | D17: 8 | E17: A | F17: 8 | G17: 8 | H17: 8 | I17: 7.3 | J17: 8 | K17: 8 | L17: 8 | M17: 8 | N17: 8 | P17: 8 | Q17: 8 | R17: 8
A18: 46154 | B18: Tue | C18: WORK | D18: 8 | E18: 8 | F18: 8 | G18: 8 | H18: 8 | I18: A | J18: 8 | K18: 8 | L18: 7.5 | M18: 7.3 | N18: 8 | P18: 8 | Q18: 8 | R18: 8
A19: 46155 | B19: Wed | C19: WORK | D19: 8 | E19: 8 | F19: 8 | G19: 8 | H19: 8 | I19: 8 | J19: 8 | K19: 8 | L19: 8 | M19: 7.5 | N19: 8 | P19: 8 | Q19: 8 | R19: 8
A20: 46156 | B20: Thu | C20: WORK | D20: 8 | E20: 8 | F20: 8 | G20: A | H20: 8 | I20: 8 | J20: 8 | K20: 8 | L20: 8 | M20: A | N20: 8 | P20: 8 | Q20: 8 | R20: 8
A21: 46157 | B21: Fri | C21: WORK | D21: 8 | E21: 8 | F21: 8 | G21: 8 | H21: 8 | I21: 8 | J21: 8 | K21: 8 | L21: 7.5 | M21: 8 | N21: 8 | P21: 8 | Q21: 8 | R21: 8
A22: 46158 | B22: Sat | C22: WORK | D22: 8 | E22: 7 | F22: 8 | G22: 8 | H22: A | I22: 7.5 | J22: 8 | K22: 8 | L22: 7.5 | M22: A | N22: 8 | P22: 8 | Q22: 8 | R22: 8
A23: 46159 | B23: OFF | C23: OFF | D23: 0 | E23: 0 | F23: 0 | G23: 0 | H23: 0 | I23: 0 | J23: 0 | K23: 0 | L23: 0 | M23: 0 | N23: 0 | O23: 0 | P23: 0 | Q23: 0 | R23: 0 | S23: 0 | T23: 0 | U23: 0 | V23: 0 | W23: 0 | X23: 0 | Y23: 0 | Z23: 0 | AA23: 0 | AB23: 0 | AC23: 0 | AD23: 0 | AE23: 0 | AF23: 0 | AG23: 0 | AH23: 0
A24: 46160 | B24: Mon | C24: WORK | D24: 8 | E24: 8 | F24: 8 | G24: 8 | H24: 8 | I24: 8 | J24: 8 | K24: 8 | L24: 8 | M24: 8 | N24: 8 | P24: 8 | Q24: 8 | R24: 8
A25: 46161 | B25: Tue | C25: WORK | D25: 8 | E25: 8 | F25: 8 | G25: 8 | H25: 7.45 | I25: 8 | J25: 8 | K25: 8 | L25: 8 | M25: 7.2 | N25: 8 | P25: 8 | Q25: 8 | R25: 8
A26: 46162 | B26: Wed | C26: WORK | D26: 8 | E26: 8 | F26: 8 | G26: 8 | H26: 7.2 | I26: 8 | J26: 8 | K26: 8 | L26: 7.5 | M26: 7.5 | N26: 8 | P26: 8 | Q26: 8 | R26: 7.3
A27: 46163 | B27: Thu | C27: WORK | D27: 8 | E27: 7.4 | F27: 8 | G27: 8 | H27: 7.5 | I27: 7.45 | J27: 8 | K27: 8 | L27: 8 | M27: 7.4 | N27: 8 | P27: 8 | Q27: 8 | R27: 8
A28: 46164 | B28: Fri | C28: WORK | D28: 8 | E28: 8 | F28: 8 | G28: 8.3 | H28: 7 | I28: 7.45 | J28: 8 | K28: 8 | L28: 8.3 | M28: 8 | N28: 8 | P28: 8 | Q28: 8 | R28: 7.45
A29: 46165 | B29: Sat | C29: WORK | D29: 8 | E29: 7.45 | F29: 8 | G29: 8 | H29: 7.45 | I29: 7.45 | J29: 8 | K29: 8 | L29: 8 | M29: 8 | N29: 8 | P29: 8 | Q29: 8 | R29: 8
A30: 46166 | B30: OFF | C30: OFF | D30: 0 | E30: 0 | F30: 0 | G30: 0 | H30: 0 | I30: 0 | J30: 0 | K30: 0 | L30: 0 | M30: 0 | N30: 0 | O30: 0 | P30: 0 | Q30: 0 | R30: 0 | S30: 0 | T30: 0 | U30: 0 | V30: 0 | W30: 0 | X30: 0 | Y30: 0 | Z30: 0 | AA30: 0 | AB30: 0 | AC30: 0 | AD30: 0 | AE30: 0 | AF30: 0 | AG30: 0 | AH30: 0
A31: 46167 | B31: Mon | C31: WORK | D31: 8 | E31: 7.4 | F31: 8 | G31: 8 | H31: 7.45 | I31: 4.4 | J31: 8 | K31: 8 | L31: 8 | M31: A | N31: 8 | P31: 8 | Q31: 8 | R31: 8
A32: 46168 | B32: Tue | C32: WORK | D32: 8 | E32: 5 | F32: 8 | G32: 8 | H32: 5 | I32: A | J32: 8 | K32: 8 | L32: 5 | M32: A | N32: 8 | P32: 8 | Q32: 8 | R32: 8
A33: 46169 | B33: Wed | C33: WORK | D33: 8 | E33: 8 | F33: 8 | G33: 8 | H33: 8 | I33: 8 | J33: 8 | K33: 8 | L33: 8 | M33: 8 | N33: 8 | P33: 8 | Q33: 8 | R33: 8
A34: 46170 | B34: Thu | C34: WORK | D34: 8 | E34: 8 | F34: 8 | G34: 8 | H34: 8 | I34: 8 | J34: 8 | K34: 8 | L34: 8 | M34: 8 | N34: 8 | P34: 8 | Q34: 8 | R34: 8
A35: 46171 | B35: Fri | C35: WORK | D35: 8 | E35: 8 | F35: 8 | G35: 8 | H35: 8 | I35: 8 | J35: 8 | K35: 8 | L35: 8 | M35: 8 | N35: 8 | P35: 8 | Q35: 8 | R35: 8
A36: 46172 | B36: Sat | C36: WORK | D36: 8 | E36: A | F36: 8 | G36: A | H36: A | I36: A | J36: 8 | K36: 8 | L36: A | M36: A | N36: 8 | P36: 8 | Q36: 8 | R36: A
A37: 46173 | B37: OFF | C37: OFF | D37: 0 | E37: 0 | F37: 0 | G37: 0 | I37: 0 | J37: 0 | K37: 0 | L37: 0 | M37: 0 | N37: 0 | O37: 0 | P37: 0 | Q37: 0 | R37: 0 | S37: 0 | T37: 0 | U37: 0 | V37: 0 | W37: 0 | X37: 0 | Y37: 0 | Z37: 0 | AA37: 0 | AB37: 0 | AC37: 0 | AD37: 0 | AE37: 0 | AF37: 0 | AG37: 0 | AH37: 0
A39: TOTALS | E39: =IF(Setup!B15<>"",SUM(E7:E37),"") -> 192.65 | F39: =IF(Setup!B16<>"",SUM(F7:F37),"") -> 208 | G39: =IF(Setup!B17<>"",SUM(G7:G37),"") -> 192.3 | H39: =IF(Setup!B18<>"",SUM(H7:H37),"") -> 182.05 | I39: =IF(Setup!B19<>"",SUM(I7:I37),"") -> 173.55 | J39: =IF(Setup!B20<>"",SUM(J7:J37),"") -> 208 | K39: =IF(Setup!B21<>"",SUM(K7:K37),"") -> 208 | L39: =IF(Setup!B22<>"",SUM(L7:L37),"") -> 193.6 | M39: =IF(Setup!B23<>"",SUM(M7:M37),"") -> 140.9 | N39: =IF(Setup!B24<>"",SUM(N7:N37),"") -> 208 | O39: =IF(Setup!B25<>"",SUM(O7:O37),"") -> 0 | P39: =IF(Setup!B26<>"",SUM(P7:P37),"") -> 208 | Q39: =IF(Setup!B27<>"",SUM(Q7:Q37),"") -> 208 | R39: =IF(Setup!B28<>"",SUM(R7:R37),"") -> 134.75 | S39: =IF(Setup!B29<>"",SUM(S7:S37),"") | T39: =IF(Setup!B30<>"",SUM(T7:T37),"") | U39: =IF(Setup!B31<>"",SUM(U7:U37),"") | V39: =IF(Setup!B32<>"",SUM(V7:V37),"") | W39: =IF(Setup!B33<>"",SUM(W7:W37),"") | X39: =IF(Setup!B34<>"",SUM(X7:X37),"") | Y39: =IF(Setup!B35<>"",SUM(Y7:Y37),"") | Z39: =IF(Setup!B36<>"",SUM(Z7:Z37),"") | AA39: =IF(Setup!B37<>"",SUM(AA7:AA37),"") | AB39: =IF(Setup!B38<>"",SUM(AB7:AB37),"") | AC39: =IF(Setup!B39<>"",SUM(AC7:AC37),"") | AD39: =IF(Setup!B40<>"",SUM(AD7:AD37),"") | AE39: =IF(Setup!B41<>"",SUM(AE7:AE37),"") | AF39: =IF(Setup!B42<>"",SUM(AF7:AF37),"") | AG39: =IF(Setup!B43<>"",SUM(AG7:AG37),"") | AH39: =IF(Setup!B44<>"",SUM(AH7:AH37),"")
